Workbook
Name defect: Validation!$C$1:$C$6
Name Status: #N/A
Name statuslist: Validation!$A$1:$A$9

Sheet Version Control
C4: Document Information
C5: Title | D5: Test Execution Log
C6: Title | D6: March Release
C7: Release Identifier | D7: RLSE0010188, RLSE0010214, RLSE0010192
C8: Author | D8: Beverley Barlow
C10: Document Version History
C11: Version | D11: Date | E11: Summary of Changes
C12: 0.1 | D12: 46056 | E12: Draft RLSE0010214
C13: 0.2 | D13: 46058 | E13: Working Copy - RLSE0010188, RLSE0010192 added
C18: Test Evidence Repository
C19: Test Execution Evidence is stored at this link | E19: Link to Test Evidence Repository
C21: Scope of Release
C22: This release implements a Servicenow upgrade
C23: Defect/Story ID | D23: Type | E23: Details
C24: STRY0089352 | D24: Enhancement | E24: 2nd WOT creation for Install at source / Tag at source fields
C25: STRY0089363 | D25: Enhancement | E25: Label change to Enforcement Action
C26: STRY0085912 | D26: Enhancement | E26: Visibility of HMU phone number within the mobile app view of the WOT
C27: STRY0085923 | D27: Enhancement | E27: Visibility of device wearer's mobile phone number within the mobile app view of the WOT
C28: STRY0085924 | D28: Enhancement | E28: Ability to make a call from within a WOT within the mobile applications
C29: STRY0085928 | D29: Enhancement | E29: Ability to make a call from within a WOT within the mobile applications to HMU
C30: STRY0085930 | D30: Enhancement | E30: Ability to mask FMO's phone number when calling DW from within the mobile application
C31: STRY0085931 | D31: Enhancement | E31: Record outcome of phone call made from within the mobile application
C32: STRY0086297 | D32: Enhancement | E32: New order playbook - additional steps - verify contact information
C33: STRY0086298 | D33: Enhancement | E33: New order playbook - additional steps - contact device wearer on order entry
C34: STRY0086330 | D34: Enhancement | E34: Ensure WOTs that need attention are highlighted to schedules
... C57: STRY0089363 | D57: Enhancement | E57: Label change to Enforcement Action

Sheet Summary
E2: Install Success Opt1-4 DASHBOARD | R2: SHEET4 DASHBOARD | AF2: OVERALL DASHBOARD
B4: Execution Progress | O4: Execution Progress | AC4: Execution Progress
B5: Steps Completed | C5: =SUM('Install Success Opt1-4'!F2:F69) -> 0 | O5: Steps Completed | P5: =SUM('Alert Regression'!F2:F38) -> 0 | AC5: Steps Completed | AD5: =SUM(OVERALL!F2:F82) -> 0
B6: Steps Remaining | C6: =C7-C5 -> 489 | O6: Steps Remaining | P6: =SUM(P7-P5) -> 156 | AC6: Steps Remaining | AD6: =SUM(AD7-AD5) -> 0
B7: Total Steps | C7: =SUM('Install Success Opt1-4'!E2:E69) -> 489 | O7: Total Steps | P7: =SUM('Alert Regression'!E2:E38) -> 156 | AC7: Total Steps | AD7: =SUM(OVERALL!E2:E82) -> 0
B9: % Complete | C9: =C5/C7 -> 0 | O9: % Complete | P9: =P5/P7 -> 0 | AC9: % Complete | AD9: =AD5/AD7 -> #DIV/0!
B11: Script Status | O11: Script Status | AC11: Script Status
B12: Pass | C12: =COUNTIF('Install Success Opt1-4'!$G$2:$G$178,Summary!B12) -> 0 | D12: =C12/$C$19 -> 0 | O12: Pass | P12: =COUNTIF('Alert Regression'!$G$2:$G$145,Summary!O12) -> 0 | Q12: =P12/$P$19 -> 0 | AC12: Pass | AD12: =COUNTIF(OVERALL!$G$2:$G$150,Summary!AC12) -> 0 | AE12: =AD12/$AD$19 -> #DIV/0!
B13: Fail | C13: =COUNTIF('Install Success Opt1-4'!$G$2:$G$178,Summary!B13) -> 0 | D13: =C13/$C$19 -> 0 | O13: Fail | P13: =COUNTIF('Alert Regression'!$G$2:$G$145,Summary!O13) -> 0 | Q13: =P13/$P$19 -> 0 | AC13: Fail | AD13: =COUNTIF(OVERALL!$G$2:$G$150,Summary!AC13) -> 0 | AE13: =AD13/$AD$19 -> #DIV/0!
B14: No Run | C14: =COUNTIF('Install Success Opt1-4'!$G$2:$G$178,Summary!B14) -> 0 | D14: =C14/$C$19 -> 0 | O14: No Run | P14: =COUNTIF('Alert Regression'!$G$2:$G$145,Summary!O14) -> 0 | Q14: =P14/$P$19 -> 0 | AC14: No Run | AD14: =COUNTIF(OVERALL!$G$2:$G$150,Summary!AC14) -> 0 | AE14: =AD14/$AD$19 -> #DIV/0!
B15: Not Completed | C15: =COUNTIF('Install Success Opt1-4'!$G$2:$G$178,Summary!B15) -> 0 | D15: =C15/$C$19 -> 0 | O15: Not Completed | P15: =COUNTIF('Alert Regression'!$G$2:$G$145,Summary!O15) -> 0 | Q15: =P15/$P$19 -> 0 | AC15: Not Completed | AD15: =COUNTIF(OVERALL!$G$2:$G$150,Summary!AC15) -> 0 | AE15: =AD15/$AD$19 -> #DIV/0!
B16: In Progress | C16: =COUNTIF('Install Success Opt1-4'!$G$2:$G$178,Summary!B16) -> 0 | D16: =C16/$C$19 -> 0 | O16: In Progress | P16: =COUNTIF('Alert Regression'!$G$2:$G$145,Summary!O16) -> 0 | Q16: =P16/$P$19 -> 0 | AC16: In Progress | AD16: =COUNTIF(OVERALL!$G$2:$G$150,Summary!AC16) -> 0 | AE16: =AD16/$AD$19 -> #DIV/0!
B17: Out of Scope | C17: =COUNTIF('Install Success Opt1-4'!$G$2:$G$178,Summary!B17) -> 0 | D17: =C17/$C$19 -> 0 | O17: Out of Scope | P17: =COUNTIF('Alert Regression'!$G$2:$G$145,Summary!O17) -> 0 | Q17: =P17/$P$19 -> 0 | AC17: Out of Scope | AD17: =COUNTIF(OVERALL!$G$2:$G$150,Summary!AC17) -> 0 | AE17: =AD17/$AD$19 -> #DIV/0!
B18: Not Started | C18: =COUNTIF('Install Success Opt1-4'!$G$2:$G$178,Summary!B18) -> 163 | D18: =C18/$C$19 -> 1 | O18: Not Started | P18: =COUNTIF('Alert Regression'!$G$2:$G$145,Summary!O18) -> 35 | Q18: =P18/$P$19 -> 1 | AC18: Not Started | AD18: =COUNTIF(OVERALL!$G$2:$G$150,Summary!AC18) -> 0 | AE18: =AD18/$AD$19 -> #DIV/0!
B19: TOTAL | C19: =SUM(C12:C18) -> 163 | O19: TOTAL | P19: =SUM(P12:P18) -> 35 | AC19: TOTAL | AD19: =SUM(AD12:AD18) -> 0
E23: March Enhancements DASHBOARD | Q23: KPI Enhancements DASHBOARD
B25: Execution Progress | O25: Execution Progress
B26: Steps Completed | C26: =SUM('March Enhancements'!F2:F59) -> 0 | O26: Steps Completed | P26: =SUM('KPI Enhancements'!F2:F21) -> 0
B27: Steps Remaining | C27: =SUM(C28-C26) -> 23 | O27: Steps Remaining | P27: =P28-P26 -> 109
B28: Total Steps | C28: =SUM('March Enhancements'!E2:E59) -> 23 | O28: Total Steps | P28: =SUM('KPI Enhancements'!E2:E21) -> 109
B30: % Complete | C30: =C26/C28 -> 0 | O30: % Complete | P30: =P26/P28 -> 0
B32: Script Status | O32: Script Status
B33: Pass | C33: =COUNTIF('March Enhancements'!$G$2:$G$149,Summary!B33) -> 0 | D33: =C33/$C$40 -> 0 | O33: Pass | P33: =COUNTIF('KPI Enhancements'!$G$2:$G$109,Summary!O33) -> 0 | Q33: =P33/$P$40 -> 0
B34: Fail | C34: =COUNTIF('March Enhancements'!$G$2:$G$149,Summary!B34) -> 0 | D34: =C34/$C$40 -> 0 | O34: Fail | P34: =COUNTIF('KPI Enhancements'!$G$2:$G$109,Summary!O34) -> 0 | Q34: =P34/$P$40 -> 0
B35: No Run | C35: =COUNTIF('March Enhancements'!$G$2:$G$149,Summary!B35) -> 0 | D35: =C35/$C$40 -> 0 | O35: No Run | P35: =COUNTIF('KPI Enhancements'!$G$2:$G$109,Summary!O35) -> 0 | Q35: =P35/$P$40 -> 0
B36: Not Completed | C36: =COUNTIF('March Enhancements'!$G$2:$G$149,Summary!B36) -> 0 | D36: =C36/$C$40 -> 0 | O36: Not Completed | P36: =COUNTIF('KPI Enhancements'!$G$2:$G$109,Summary!O36) -> 0 | Q36: =P36/$P$40 -> 0
B37: In Progress | C37: =COUNTIF('March Enhancements'!$G$2:$G$149,Summary!B37) -> 0 | D37: =C37/$C$40 -> 0 | O37: In Progress | P37: =COUNTIF('KPI Enhancements'!$G$2:$G$109,Summary!O37) -> 0 | Q37: =P37/$P$40 -> 0
B38: Out of Scope | C38: =COUNTIF('March Enhancements'!$G$2:$G$149,Summary!B38) -> 0 | D38: =C38/$C$40 -> 0 | O38: Out of Scope | P38: =COUNTIF('KPI Enhancements'!$G$2:$G$109,Summary!O38) -> 0 | Q38: =P38/$P$40 -> 0
B39: Not Started | C39: =COUNTIF('March Enhancements'!$G$2:$G$149,Summary!B39) -> 7 | D39: =C39/$C$40 -> 1 | O39: Not Started | P39: =COUNTIF('KPI Enhancements'!$G$2:$G$109,Summary!O39) -> 58 | Q39: =P39/$P$40 -> 1
B40: TOTAL | C40: =SUM(C33:C39) -> 7 | O40: TOTAL | P40: =SUM(P33:P39) -> 58

Sheet Install Success Opt1-4
A1: Test ID | B1: Test Scenario | C1: Test Steps | D1: Outcome Expected | E1: # of Steps | F1: Completed Steps | G1: Status | H1: Notes | I1: Data notes | J1: Tested by | K1: Story
A2: IS157 | B2: Adult - Text message not sent to device wearer for Specials New Monitoring Order Cases | C2: 1. create a new interaction 2. create a new device wearer (with mobile number) 3. create a new monitoring order case 4. create work order 5. create work order task 6. SMS will not send to the device wearer | D2: SMS will not be sent to the device wearer following the creation of the new monitoring order case | E2: 6 | G2: Not Started | K2: SPECIALS REGRESSION
A3: IS158 | B3: Adult - text message not sent to device wearer when install 1st attempt WOT is assigned to FMO | C3: 1. assign install 1st attempt WOT (created in IS157) to FMO 2. sms will not send to the device wearer 3. check work notes of WOT to ensure sms not sent | D3: SMS will not be sent to the device wearer following a WOT being assigned to an fmo | E3: 3 | G3: Not Started | H3: continued from IS157 | K3: SPECIALS REGRESSION
A4: IS159 | B4: Adult - text message not sent to device wearer when FMO starts travel | C4: 1. FMO receives install 1st attempt WOT (assigned in IS158) 2. FMO selects accept on their agent app 3. FMO selects start travel on their agent app 4. state of WOT updates to 'on route' 5. SMS will not send to the device wearer 6. check work notes of WOT to ensure SMS not sent | D4: SMS will not be sent to the device wearer following an fmo selecting 'start travel' on their app | E4: 6 | G4: Not Started | H4: continued from IS158 | K4: SPECIALS REGRESSION
A5: IS160 | B5: Adult - text message not sent to device wearer when decom WOT is assigned to FMO | C5: 1. create decom WOT 2. assign install decom WOT to FMO 3. SMS will not send to the device wearer 4. check work notes of WOT to ensure SMS not sent | D5: SMS will not be sent to the device wearer following a WOT being assigned to an fmo | E5: 4 | G5: Not Started | K5: SPECIALS REGRESSION
A6: IS161 | B6: Adult - text message not sent to device wearer when FMO starts travel | C6: 1. FMO receives decom WOT (assigned in IS160) 2. FMO selects accept on their agent app 3. FMO selects start travel on their agent app 4. state of WOT updates to 'on route' 5. SMS will not send to the device wearer 6. check work notes of WOT to ensure SMS not sent | D6: SMS will not be sent to the device wearer following an fmo selecting 'start travel' on their app | E6: 6 | G6: Not Started | H6: continued from IS160 | K6: SPECIALS REGRESSION
A7: IS162 | B7: Adult - text message not sent to device wearer when tamper WOT is assigned to FMO | C7: 1. create tamper WOT 2. assign install tamper WOT to FMO 2. SMS will not send to the device wearer 3. check work notes of WOT to ensure SMS not sent | D7: SMS will not be sent to the device wearer following a WOT being assigned to an fmo | E7: 3 | G7: Not Started | K7: SPECIALS REGRESSION
A8: IS163 | B8: Adult - text message not sent to device wearer when FMO starts travel | C8: 1. FMO receives tamper WOT (assigned in IS162) 2. FMO selects accept on their agent app 3. FMO selects start travel on their agent app 4. state of WOT updates to 'on route' 5. SMS will not send to the device wearer 6. check work notes of WOT to ensure SMS not sent | D8: SMS will not be sent to the device wearer following an fmo selecting 'start travel' on their app | E8: 6 | G8: Not Started | H8: continued from IS163 | K8: SPECIALS REGRESSION
A9: IS01 | B9: Visibility of HMU phone number within the mobile app view of the WOT | C9: 1.Create a new order 2. Install HMU & SOLO 3. Ensure HMU number is in the 'Contact Devices' field in Device Wearer 4.Create an equipment check WOT 5. Assign WOT to FMO 6. FMO receives WOT on Agent App 7. Ensure HMU phone number is displayed on the WOT information | D9: Correct HMU phone number displays on the WOT - Ensure HMU phone number matches the HMU phone number that is installed at the WOT address | E9: 7 | G9: Not Started | K9: STRY0085912
A10: IS02 | B10: Visibility of Device Wearer's mobile phone number within the mobile app view of the WOT | C10: 1. Create a new order 2. Ensure Device Wearer's mobile number is in the mobile phone field in Device Wearer 3.Create an install WOT 4. Assign WOT to FMO 5. FMO receives WOT on Agent App 6. Ensure DW mobile phone number is displayed on the WOT information | D10: Device Wearer's phone number displays on the WOT - Ensure phone number matches the phone number on the Device Wearer's profile | E10: 6 | G10: Not Started | K10: STRY0085923
A11: IS03 | B11: Ability to make a call from within a WOT within the mobile applications | C11: 1. Create a new order 2. Ensure Device Wearer's mobile number is in the mobile phone field in Device Wearer 3.Create an install WOT 4. Assign WOT to FMO 5. FMO receives WOT on Agent App 6. DW mobile phone number visible 7. Option to call displayed at the right of the DW mobile phone number 8. FMO selects the option to call 9. Phone call to DW starts 10. Phone call recorded in the 'activity' section of the WOT | D11: FMOs will have the option to call the mobile phone that is displayed on the agent app - call will then be made to the Device Wearer Phone call will then be recorded in the activity within the WOT | E11: 10 | G11: Not Started | K11: STRY0085924
A12: IS04 | B12: Ability to make a call from within a WOT within the mobile applications to HMU | C12: 1. Install HMU & SOLO 2. Ensure HMU number is in the 'Contact Devices' field in Device Wearer 3.Create an equipment check WOT 4. Assign WOT to FMO 5. FMO receives WOT on Agent App 6. HMU phone number visible 7. Option to call displayed at the right of the HMU phone number 8. FMO selects the option to call 9. Phone call to DW'S HMU starts 10. Phone call recorded in the 'activity' section of the WOT | D12: FMOs will have the option to call the HMU phone number that is displayed on the agent app - call will then be made to the Device Wearer's HMU Phone call will then be recorded in the activity within the WOT | E12: 10 | G12: Not Started | K12: STRY0085928
A13: IS05 | B13: Ability to mask FMO's phone number when calling DW from within the mobile application Part 1 - HMU | C13: 1. FMO assigned WOT 2. HMU phone number visible 3. Option to call displayed at the right of the HMU phone number 4. FMO selects the option to call 5. Phone call to DW's HMU starts 6. Device Wearer receives call from withheld number | D13: Device Wearers will not see the FMOs phone number when the FMO calls | E13: 6 | G13: Not Started | K13: STRY0085930
A14: IS06 | B14: Ability to mask FMO's phone number when calling DW from within the mobile application Part 2 - Mobile | C14: 1. FMO assigned WOT 2. DW mobile phone number visible 3. Option to call displayed at the right of the mobile number 4. FMO selects the option to call 5. Phone call to DW's mobile number starts 6. Device Wearer receives call from withheld number | D14: Device Wearers will not see the FMOs phone number when the FMO calls | E14: 6 | G14: Not Started | K14: STRY0085930
A15: IS07 | B15: Record outcome of phone call made from within the mobile application Part 1 - Call Unanswered | C15: 1. FMO assigned WOT 2. HMU phone number / mobile number visible 3. FMO selects the option to call 5. Phone call to HMU / Mobile starts 6. Device Wearer receives call from withheld number 7. Call not answered 8. FMO selects Call Outcome - 'Call Unanswered' | D15: FMO records outcome of the phone call - 'Call unanswered' | E15: 9 | G15: Not Started | H15: linked to IS15 | K15: STRY0085931 / STRY0087283
A16: IS08 | B16: Record outcome of phone call made from within the mobile application Part 2 - Call Answered - Available | C16: 1. FMO assigned WOT 2. HMU phone number / mobile number visible 3. FMO selects the option to call 5. Phone call to HMU / Mobile starts 6. Device Wearer receives call from witheld number 7. Call answered - Device Wearer confirmed they are available 8. FMO selects Call Outcome - 'Call Answered-Available' | D16: FMO records outcome of the phone call with the Device Wearer - 'Call answered-available' | E16: 9 | G16: Not Started | H16: linked to IS16 | K16: STRY0085931 / STRY0087283
A17: IS09 | B17: Record outcome of phone call made from within the mobile application Part 3 - Call Answered - Device Wearer unavailable | C17: 1. FMO assigned WOT 2. HMU phone number / Mobile visible 3. FMO selects the option to call 5. Phone call to HMU / Mobile starts 6. Device Wearer receives call from withheld number 7. Call answered - Device Wearer confirmed they are not available 8. FMO selects Call Outcome - 'Call Answered-Device Wearer unavailable' | D17: FMO records outcome of the phone call with the Device Wearer - 'call answered-device wearer unavailable' | E17: 9 | G17: Not Started | H17: linked to IS13 | K17: STRY0085931 / STRY0087283
A18: IS10 | B18: Record outcome of phone call made from within the mobile application Part 4 - Call Unanswered - Voicemail left | C18: 1. FMO assigned WOT 2. HMU phone number / Mobile visible 3. FMO selects the option to call 5. Phone call to HMU / Mobile starts 6. Device Wearer receives call from withheld number 7. Call not answered - FMO leaves voicemail 8. FMO selects Call Outcome - 'Call unanswered - voicemail left' | D18: FMO records outcome of the phone call - 'call unanswered - voicemail left' | E18: 9 | G18: Not Started | H18: linked to IS17 | K18: STRY0085931 / STRY0087283
A19: IS11 | B19: Record outcome of phone call made from within the mobile application Part 5 - Call Answered - other | C19: 1. FMO assigned WOT 2. HMU phone number / Mobile visible 3. FMO selects the option to call 5. Phone call to HMU / Mobile starts 6. Device Wearer receives call from withheld number 7. Call answered - Device Wearer refused access 8. FMO selects Call Outcome - 'Call Answered-other' | D19: FMO records outcome of the phone call with the Device Wearer - 'Call answered-other' | E19: 9 | G19: Not Started | H19: linked to IS14 | K19: STRY0085931 / STRY0087283
A20: IS12 | B20: Record outcome of phone call made from within the mobile application Part 6 - No number listed | C20: 1. FMO assigned WOT 2. No HMU phone number / Mobile visible 3. FMO unable to select option to call 4. Call Outcome prepopulated as 'No number listed' | D20: Call outcome prepopulated as 'No number listed' | E20: 4 | G20: Not Started | H20: linked to IS18 & IS24 | K20: STRY0085931 / STRY0087283
A21: IS31 | B21: New order playbook - additional steps - verify contact information Non-CEMO - Adult - Bail | C21: 1. create a new interaction 2. create a new device wearer 3. create a new monitoring case 4. follow the playbook - after the 'Check Device Wearer attributes received are accurate..' playbook step, ensure a new playbook section 'Contact Number Review appears 5. ensure new playbook step 'Confirm Contact Details' appears 6. ensure correct device wearer displays 7. update the mobile number field 8. enter a work note in the 'work notes' field 9. select 'update' 10. check mobile phone field on the device wearer - ensure this has updated 11. select 'mark complete' on the playbook step | D21: New playbook step 'confirm contact details' appears in the New Monitoring Order case playbook | E21: 11 | G21: Not Started | K21: STRY0086297
A22: IS32 | B22: New order playbook - additional steps - verify contact information Non-CEMO - Adult - Non-Bail | C22: 1. create a new interaction 2. create a new device wearer 3. create a new monitoring case 4. follow the playbook - after the 'Check Device Wearer attributes received are accurate..' playbook step, ensure a new playbook section 'Contact Number Review appears 5. ensure new playbook step 'Confirm Contact Details' appears 6. ensure correct device wearer displays 7. update the mobile number field 8. enter a work note in the 'work notes' field 9. select 'update' 10. check mobile phone field on the device wearer - ensure this has updated 11. select 'mark complete' on the playbook step | D22: New playbook step 'confirm contact details' appears in the New Monitoring Order case playbook | E22: 11 | G22: Not Started | K22: STRY0086297
A23: IS33 | B23: New order playbook - additional steps - verify contact information Non-CEMO - Adult - Immigration | C23: 1. create a new interaction 2. create a new device wearer 3. create a new monitoring case 4. follow the playbook - after the 'Check Device Wearer attributes received are accurate..' playbook step, ensure a new playbook section 'Contact Number Review appears 5. ensure new playbook step 'Confirm Contact Details' appears 6. ensure correct device wearer displays 7. update the mobile number field 8. enter a work note in the 'work notes' field 9. select 'update' 10. check mobile phone field on the device wearer - ensure this has updated 11. select 'mark complete' on the playbook step | D23: New playbook step 'confirm contact details' appears in the New Monitoring Order case playbook | E23: 11 | G23: Not Started | K23: STRY0086297
A24: IS34 | B24: New order playbook - additional steps - verify contact information Non-CEMO - Adult - Alcohol | C24: 1. create a new interaction 2. create a new device wearer 3. create a new monitoring case 4. follow the playbook - after the 'Check Device Wearer attributes received are accurate..' playbook step, ensure a new playbook section 'Contact Number Review appears 5. ensure new playbook step 'Confirm Contact Details' appears 6. ensure correct device wearer displays 7. update the mobile number field 8. enter a work note in the 'work notes' field 9. select 'update' 10. check mobile phone field on the device wearer - ensure this has updated 11. select 'mark complete' on the playbook step | D24: New playbook step 'confirm contact details' appears in the New Monitoring Order case playbook | E24: 11 | G24: Not Started | K24: STRY0086297
A25: IS35 | B25: New order playbook - additional steps - verify contact information Non-CEMO - Adult - Acquisitive Crime | C25: 1. create a new interaction 2. create a new device wearer 3. create a new monitoring case 4. follow the playbook - after the 'Check Device Wearer attributes received are accurate..' playbook step, ensure a new playbook section 'Contact Number Review appears 5. ensure new playbook step 'Confirm Contact Details' appears 6. ensure correct device wearer displays 7. update the mobile number field 8. enter a work note in the 'work notes' field 9. select 'update' 10. check mobile phone field on the device wearer - ensure this has updated 11. select 'mark complete' on the playbook step | D25: New playbook step 'confirm contact details' appears in the New Monitoring Order case playbook | E25: 11 | G25: Not Started | K25: STRY0086297
A26: IS36 | B26: New order playbook - additional steps - verify contact information Non-CEMO - Child - Bail | C26: 1. create a new interaction 2. create a new device wearer 3. create a new monitoring case 4. follow the playbook - after the 'Check Device Wearer attributes received are accurate..' playbook step, ensure a new playbook section 'Contact Number Review appears 5. ensure new playbook step 'Confirm Contact Details' appears 6. ensure correct device wearer displays 7. update the mobile number field 8. enter a work note in the 'work notes' field 9. select 'update' 10. check mobile phone field on the device wearer - ensure this has updated 11. select 'mark complete' on the playbook step | D26: New playbook step 'confirm contact details' appears in the New Monitoring Order case playbook | E26: 11 | G26: Not Started | K26: STRY0086297
A27: IS37 | B27: New order playbook - additional steps - verify contact information Non-CEMO - Child - Non-Bail | C27: 1. create a new interaction 2. create a new device wearer 3. create a new monitoring case 4. follow the playbook - after the 'Check Device Wearer attributes received are accurate..' playbook step, ensure a new playbook section 'Contact Number Review appears 5. ensure new playbook step 'Confirm Contact Details' appears 6. ensure correct device wearer displays 7. update the mobile number field 8. enter a work note in the 'work notes' field 9. select 'update' 10. check mobile phone field on the device wearer - ensure this has updated 11. select 'mark complete' on the playbook step | D27: New playbook step 'confirm contact details' appears in the New Monitoring Order case playbook | E27: 11 | G27: Not Started | K27: STRY0086297
A28: IS38 | B28: New order playbook - additional steps - verify contact information CEMO - Adult - Post release | C28: 1. create a new interaction 2. create a new device wearer 3. create a new monitoring case 4. follow the playbook - after the 'Check Device Wearer attributes received are accurate..' playbook step, ensure a new playbook section 'Contact Number Review appears 5. ensure new playbook step 'Confirm Contact Details' appears 6. ensure correct device wearer displays 7. update the mobile number field 8. enter a work note in the 'work notes' field 9. select 'update' 10. check mobile phone field on the device wearer - ensure this has updated 11. select 'mark complete' on the playbook step | D28: New playbook step 'confirm contact details' appears in the New Monitoring Order case playbook | E28: 11 | G28: Not Started | K28: STRY0086297
A29: IS39 | B29: New order playbook - additional steps - verify contact information CEMO - Adult - Immigration | C29: 1. create a new interaction 2. create a new device wearer 3. create a new monitoring case 4. follow the playbook - after the 'Check Device Wearer attributes received are accurate..' playbook step, ensure a new playbook section 'Contact Number Review appears 5. ensure new playbook step 'Confirm Contact Details' appears 6. ensure correct device wearer displays 7. update the mobile number field 8. enter a work note in the 'work notes' field 9. select 'update' 10. check mobile phone field on the device wearer - ensure this has updated 11. select 'mark complete' on the playbook step | D29: New playbook step 'confirm contact details' appears in the New Monitoring Order case playbook | E29: 11 | G29: Not Started | K29: STRY0086297
A30: IS40 | B30: New order playbook - additional steps - verify contact information CEMO - Adult - DAPO | C30: 1. create a new interaction 2. create a new device wearer 3. create a new monitoring case 4. follow the playbook - after the 'Check Device Wearer attributes received are accurate..' playbook step, ensure a new playbook section 'Contact Number Review appears 5. ensure new playbook step 'Confirm Contact Details' appears 6. ensure correct device wearer displays 7. update the mobile number field 8. enter a work note in the 'work notes' field 9. select 'update' 10. check mobile phone field on the device wearer - ensure this has updated 11. select 'mark complete' on the playbook step | D30: New playbook step 'confirm contact details' appears in the New Monitoring Order case playbook | E30: 11 | G30: Not Started | K30: STRY0086297
A31: IS41 | B31: New order playbook - additional steps - verify contact information CEMO - Child - Post release | C31: 1. create a new interaction 2. create a new device wearer 3. create a new monitoring case 4. follow the playbook - after the 'Check Device Wearer attributes received are accurate..' playbook step, ensure a new playbook section 'Contact Number Review appears 5. ensure new playbook step 'Confirm Contact Details' appears 6. ensure correct device wearer displays 7. update the mobile number field 8. enter a work note in the 'work notes' field 9. select 'update' 10. check mobile phone field on the device wearer - ensure this has updated 11. select 'mark complete' on the playbook step | D31: New playbook step 'confirm contact details' appears in the New Monitoring Order case playbook | E31: 11 | G31: Not Started | K31: STRY0086297
A32: IS42 | B32: New order playbook - additional steps - contact device wearer on order entry Non-CEMO - Adult - Bail | C32: 1. create a new interaction 2. create a new device wearer 3. create a new monitoring case 4. follow the playbook - after the 'Parts required' playbook step, ensure a new playbook step 'Contact Device Wearer' appears 5. select 'skip' button | D32: New playbook step 'contact device wearer' appears in the New Monitoring Order case playbook | E32: 5 | G32: Not Started | H32: continuing from IS31 | K32: STRY0086298
A33: IS43 | B33: New order playbook - additional steps - contact device wearer on order entry Non-CEMO - Adult - Non-bail | C33: 1. create a new interaction 2. create a new device wearer 3. create a new monitoring case 4. follow the playbook - after the 'Parts required' playbook step, ensure a new playbook step 'Contact Device Wearer' appears 5. select 'skip' button | D33: New playbook step 'contact device wearer' appears in the New Monitoring Order case playbook | E33: 5 | G33: Not Started | H33: continuing from IS32 | K33: STRY0086298
A34: IS44 | B34: New order playbook - additional steps - contact device wearer on order entry Non-CEMO - Adult - Immigration | C34: 1. create a new interaction 2. create a new device wearer 3. create a new monitoring case 4. follow the playbook - after the 'Parts required' playbook step, ensure a new playbook step 'Contact Device Wearer' appears 5. select 'skip' button | D34: New playbook step 'contact device wearer' appears in the New Monitoring Order case playbook | E34: 5 | G34: Not Started | H34: continuing from IS33 | K34: STRY0086298
A35: IS45 | B35: New order playbook - additional steps - contact device wearer on order entry Non-CEMO - Adult - Alcohol | C35: 1. create a new interaction 2. create a new device wearer 3. create a new monitoring case 4. follow the playbook - after the 'Parts required' playbook step, ensure a new playbook step 'Contact Device Wearer' appears 5. select 'skip' button | D35: New playbook step 'contact device wearer' appears in the New Monitoring Order case playbook | E35: 5 | G35: Not Started | H35: continuing from IS34 | K35: STRY0086298
A36: IS46 | B36: New order playbook - additional steps - contact device wearer on order entry Non-CEMO - Adult - Acquisitive Crime | C36: 1. create a new interaction 2. create a new device wearer 3. create a new monitoring case 4. follow the playbook - after the 'Parts required' playbook step, ensure a new playbook step 'Contact Device Wearer' appears 5. select 'skip' button | E36: 5 | G36: Not Started | H36: continuing from IS35 | K36: STRY0086298
A37: IS47 | B37: New order playbook - additional steps - contact device wearer on order entry Non-CEMO - Child - Bail | C37: 1. create a new interaction 2. create a new device wearer 3. create a new monitoring case 4. follow the playbook - after the 'Parts required' playbook step, ensure a new playbook step 'Contact Device Wearer' appears 5. select 'skip' button | D37: New playbook step 'contact device wearer' appears in the New Monitoring Order case playbook | E37: 5 | G37: Not Started | H37: continuing from IS36 | K37: STRY0086298
A38: IS48 | B38: New order playbook - additional steps - contact device wearer on order entry Non-CEMO - Child - Non Bail | C38: 1. create a new interaction 2. create a new device wearer 3. create a new monitoring case 4. follow the playbook - after the 'Parts required' playbook step, ensure a new playbook step 'Contact Device Wearer' appears 5. select 'skip' button | D38: New playbook step 'contact device wearer' appears in the New Monitoring Order case playbook | E38: 5 | G38: Not Started | H38: continuing from IS37 | K38: STRY0086298
A39: IS49 | B39: New order playbook - additional steps - contact device wearer on order entry CEMO - Adult - Post release | C39: 1. create a new interaction 2. create a new device wearer 3. create a new monitoring case 4. follow the playbook - after the 'Parts required' playbook step, ensure a new playbook step 'Contact Device Wearer' appears 5. select 'skip' button | D39: New playbook step 'contact device wearer' appears in the New Monitoring Order case playbook | E39: 5 | G39: Not Started | H39: continuing from IS38 | K39: STRY0086298
A40: IS50 | B40: New order playbook - additional steps - verify contact information CEMO - Adult - Immigration | C40: 1. create a new interaction 2. create a new device wearer 3. create a new monitoring case 4. follow the playbook - after the 'Check Device Wearer attributes received are accurate..' playbook step, ensure a new playbook section 'Contact Number Review appears 5. ensure new playbook step 'Confirm Contact Details' appears 6. ensure correct device wearer displays 7. update the mobile number field 8. enter a work note in the 'work notes' field 9. select 'update' 10. check mobile phone field on the device wearer - ensure this has updated 11. select 'mark complete' on the playbook step | D40: New playbook step 'confirm contact details' appears in the New Monitoring Order case playbook | E40: 11 | G40: Not Started | H40: continuing from IS39 | K40: STRY0086298
...

Sheet KPI Enhancements
A1: Test ID | B1: Test Scenario | C1: Test Steps | D1: Outcome Expected | E1: # of Steps | F1: Completed Steps | G1: Status | H1: Notes | I1: Data notes | J1: Tested by | K1: Story
A2: KP01 | B2: Hide Order Cease request field on the monitoring order-Bail | C2: - create interaction - create DW - create case - create monitoring order - create Mon Req - create Mon Con - create WO - create WOT | D2: - order cease request field no longer displayed on monitoring order - Mon Order saved | E2: 8 | G2: Not Started | K2: STRY0072638
A3: KP02 | B3: Violation case Closed state Hidden | C3: - Identify Violation case - navigate to the state | D3: Closed state not Presented | E3: 2 | G3: Not Started | K3: STRY0086778
A4: KP03 | B4: KPI6-AL02-Call Made-Answered | C4: AL02 has been created - API to PD displayed in activity stream - call made to HMU - call answered - call ends - update investigation outcome field on case to Violation confirmed - update resolution field to completed - update state to resolved | D4: -Interaction created in ServiceNow with Short description: AL02 Tamper of worn device non curfew order - auto set first response date and time field in table - First Call Outcome data field populated on case - interaction updated as Closed Complete - investigation outcome field set to Violation confirmed - resolution field set to completed - state set to resolved | E4: 8 | G4: Not Started | K4: STRY0088560
A5: KP04 | B5: KPI6-AL20-Call Made-Closed Abandoned | C5: AL20 has been created - API triggered to PD Non compliance campaign - PD call made to HMU - call abandon - set interaction state to Closed Abandoned - on case select 'Violation confirmed' in Investigation Outcome field - set case state to resolved - insert text in Work notes (private) - insert Complete in Resolution code - insert text in Resolution notes - select Save | D5: - API to PD displayed in activity stream - interaction created - chat summary updated on interaction - interaction set to Closed Abandoned state - interaction updated to Closed Abandoned state - case set to resolved and data fields updated | E5: 13 | G5: Not Started | K5: STRY0088560
A6: KP05 | B6: AL20 - Auto resolution of cases and promotion to enforcement-Closed Complete | C6: AL20 case has been created - within FMO app complete Equipment Check visit report - complete work order task as closed complete | D6: - WOT state set to Closed Complete - AL20 state auto set to resolved | E6: 3 | G6: Not Started | K6: STRY0089991
A7: KP06 | B7: AL20 - Auto resolution of cases and promotion to enforcement-Health & Safety | C7: AL20 case has been created - within FMO app complete Equipment Check visit report - complete work order task as unsuccessful -reason for unsuccessful is health and safety | D7: WOT state set to Closed Incomplete AL20 to promote to enforcement: Reason for non compliance = Health & Safety Category = Other Subcategory = 103 - No movement of device wearer | E7: 3 | G7: Not Started | K7: STRY0089991
A8: KP07 | B8: AL20 - Auto resolution of cases and promotion to enforcement-No Show | C8: AL20 case has been created - within FMO app complete Equipment Check visit report - complete work order task as unsuccessful | D8: WOT state set to Closed Incomplete AL20 to promote to enforcement: Reason for non compliance = no show Category = Other Subcategory = 103 - No movement of device wearer | E8: 3 | G8: Not Started | K8: STRY0089991
A9: KP08 | B9: AL20 - Auto resolution of cases and promotion to enforcement-withdrawl of consent | C9: AL20 case has been created - within FMO app complete Equipment Check report -complete work order task as unsuccessful | D9: WOT state set to Closed Incomplete AL20 to promote to enforcement: Reason for non compliance = Withdrawal of Consent Category = Other Subcategory = 103 - No movement of device wearer | E9: 3 | G9: Not Started | K9: STRY0089991
A10: KP09 | B10: AL20 - Auto resolution of cases and promotion to enforcement- Unable to Locate | C10: AL20 case has been created - within FMO app complete Equipment Check report - complete work order task as unsuccessful | D10: WOT state set to Unsuccessful Closed/Incomplete AL20 to promote to enforcement: Reason for non compliance = Unable to Locate Category = Other Subcategory = 103 - No movement of device wearer | E10: 3 | G10: Not Started | K10: STRY0089991
A11: KP10 | B11: Make investigation outcome field mandatory when resolving a specials alert case | C11: create AL01B Alert -Viloation Confirmed -Breach Pack created -Reslove case -Investigation outcome field is mandatory | D11: Case state resolved Investigation Outcome' field will become mandatory | E11: 5 | G11: Not Started | K11: STRY0086890
A12: KP11 | B12: KPI6-AL03- not answered | C12: AL03 has been created - API to PD displayed in activity stream - call made to HMU - call not answered - update investigation outcome field to Violation confirmed - update resolution field to completed - update state to resolved | D12: - API to PD displayed in activity stream - auto set first response date and time field in table - First Call Outcome data field populated on case - no interaction created - investigation outcome field set to Violation confirmed - resolution field set to completed - state set to resolved" | E12: 8 | G12: Not Started | K12: Regression
A13: KP12 | B13: KPI6-AL08- answered | C13: AL08 has been created - API to PD displayed in activity stream - call made to HMU - call answered - call ends - update investigation outcome field on case to Violation confirmed - update resolution field to completed - update state to resolved -return home late alert generated | D13: -Interaction created in ServiceNow with Short description: AL08 Out Past Curfew Commencement - auto set first response date and time field in table - First Call Outcome data field populated on case - interaction updated as Closed Complete - investigation outcome field set to Violation confirmed - resolution field set to completed - state set to resolved -case closed automatically after 6 hours -AL09 Is Added to AL08 | E13: 8 | G13: Not Started | K13: Regression
... A59: KP58 | B59: Default to Europe/London TimeZone | C59: -create interaction - create DW - create case - create monitoring order - create Mon Req - create schedule for curfew - default to europe/london time zone - create Mon Con - create WO - create WOT | D59: - Time zone field defaulted to Europe/london | E59: 10 | G59: Not Started | K59: STRY0090384

Sheet March Enhancements
A1: Test ID | B1: Test Scenario | C1: Test Steps | D1: Outcome Expected | E1: # of Steps | F1: Completed Steps | G1: Status | H1: Notes | I1: Data notes | J1: Tested by | K1: Story
A2: ME01 | B2: Label change to Enforcement Action | C2: - access an Enforcement case - select Enforcement Actions - select existing Pending Action record - select Device Wearer Arrested on Section 9 - select save | D2: - enforceable action updated to Device Wearer Arrested on Section 9 | E2: 5 | G2: Not Started | K2: STRY0089363
A3: ME02 | B3: Label change to Enforcement Action | C3: - access an Enforcement case - select Enforcement Actions - select existing Pending Action record - select Device Wearer Detained - select save | D3: - enforceable action updated to Device Wearer Detained | E3: 5 | G3: Not Started | K3: STRY0089363
A4: ME03 | B4: 2nd WOT Tag at source - closed complete no install location populated | C4: - create order with TAS location only - close complete TAS WOT | D4: - no 2nd WOT generated | E4: 2 | G4: Not Started | K4: STRY0089352
A5: ME04 | B5: 2nd WOT Tag at source - closed incomplete, install location populated | C5: - create order with TAS location and install location - close complete TAS WOT - close complete 2nd WOT | D5: - 2nd WOT created for install location | E5: 3 | G5: Not Started | K5: STRY0089352
A6: ME05 | B6: 2nd WOT Tag at source - closed incomplete no install location populated, DW has primary address | C6: - create order with TAS location only - close incomplete TAS WOT - close complete 2nd WOT | D6: - 2nd WOT created for DW primary address on DW form | E6: 3 | G6: Not Started | K6: STRY0089352
A7: ME06 | B7: 2nd WOT Tag at source - closed incomplete no install location populated, DW has NFA | C7: - create order with TAS location only - close incomplete TAS WOT - close complete 2nd WOT | D7: - 2nd WOT created for blank location | E7: 3 | G7: Not Started | K7: STRY0089352
A8: ME07 | B8: 2nd WOT Install at source pilot - closed complete no install location populated | C8: - create order with IAS location only - close complete IAS WOT | D8: - no 2nd WOT generated | E8: 2 | G8: Not Started | K8: STRY0089352

Sheet Alert Regression
A1: Test ID | B1: Test Scenario | C1: Test Steps | D1: Outcome Expected | E1: # of Steps | F1: Completed Steps | G1: Status | H1: Notes | I1: Data notes | J1: Tested by | K1: Story
A2: AR01 | B2: Bail - Curfew and Exclusion - 15 minutes in 1 event | C2: - create out at start of curfew event - create return home late event after 15 mins - create breach pack | D2: - AL08 case generated - AL09 added to the AL08 - AL13 case generated | E2: 3 | G2: Not Started | J2: MHI/ EA | K2: Regression
A3: AR02 | B3: Bail - Curfew and Exclusion - 15 minutes over 2 events in same curfew, 2nd event no return | C3: - create out at start of curfew event - create return home during curfew after 10 mins - create left home during curfew after 5 mins - check AL13 generated after 15 mins - create the breach pack - create a return home late event | D3: - AL08 case generated - AL09 added to the AL08 - AL10 case generated - AL13 case generated - AL09 is added to the AL10 | E3: 6 | G3: Not Started | J3: MHI/ EA | K3: Regression
A4: AR03 | B4: Bail - Curfew and Exclusion 15 minutes over 2 events in different curfews | C4: - create left home during 1st curfew - create returned home during curfew after 7mins - create left home during 2nd curfew - create returned home during curfew after 10mins | D4: - AL10 case generated - AL09 is added to the AL10 - AL10 case generated - AL09 is added to the AL10 | E4: 4 | G4: Not Started | J4: MHI/ EA | K4: Regression
A5: AR04 | B5: DAPO - Curfew only - 15 minutes in 1 event | C5: - create out at start of curfew event - create return home late event after 15 mins - create breach pack | D5: '-AL08 case generated - AL13 case generated | E5: 3 | G5: Not Started | J5: MHI/ EA | K5: Regression
A6: AR05 | B6: DAPO - Curfew only - 15 minutes over 2 events in same curfew, 2nd event no return | C6: - create out at start of curfew event - create return home during curfew after 10 mins - create left home during curfew after 5 mins - check AL13 generated after 15 mins - create the breach pack - create a return home late event | D6: - AL08 case generated - AL13 case generated | E6: 6 | G6: Not Started | J6: MHI/ EA | K6: Regression
A7: AR06 | B7: DAPO - Curfew only - 15 minutes over 2 events in different curfews | C7: - create left home during 1st curfew - create returned home during curfew after 7 mins - create left home during 2nd curfew - create returned home during curfew after 10 mins | D7: - AL10 case generated - AL09 is added to the AL10 - AL10 case generated - AL09 is added to the AL10 | E7: 4 | G7: Not Started | J7: MHI/ EA | K7: Regression
A8: AR07 | B8: Non-Bail - Curfew and Exclusion - 2 hours in 1 event for same curfew period | C8: - create out at start of curfew event - create return home late event after 2 hours - check AL13 Generated - create breach pack | D8: - AL08 case generated - AL09 added to the AL08 - AL13 case generated | E8: 4 | G8: Not Started | J8: MHI/ EA | K8: Regression
A9: AR08 | B9: Non-Bail - Curfew and Exclusion - 3 hours over 2 events for the same curfew period | C9: - create out at start of curfew event - create return home late event after 2 hours - create a left during curfew after 30 mins - create a return home late after 30 mins - create breach pack - check next day the ATV resets | D9: - AL08 case generated - AL09 added to the AL08 - AL10 case generated - AL13 case generated - AL09 is added to the AL10 | E9: 6 | G9: Not Started | J9: MHI/ EA | K9: Regression
A10: AR09 | B10: Immigration - GPS - AL06 - Multiple events | C10: - enter exclsuion zone - depart exculsion zone - do the top two events multiple times through the day - AL06 case generated and all exclusion events up to 6.59am included - AL06 case generated | D10: Generate breach pack after 07:00am | E10: 5 | G10: Not Started | J10: LJ | K10: Regression
A11: AR10 | B11: NFD - Order creation and missed biometric | C11: - Install NFD - When alert for biometric generates use a fingerprint not used on install - Create Breach | D11: AL18 Generated | E11: 3 | G11: Not Started | J11: LJ | K11: Regression
A12: AR11 | B12: Immigration - Strap Tamper | C12: 1. Generate tamper 2.AL02-Generated 3. Create visit to comfirm Tamper 4. Book off as confirmed tamper 5. Create breach | D12: AL104 manually Generated after visit | E12: 5 | G12: Not Started | J12: LJ | K12: Regression
A13: AR12 | B13: Bail - Child- Curfew and Exclusion - 15 minutes in 1 event | C13: - create out at start of curfew event - create return home late event after 15 mins - create breach pack | D13: - AL08 case generated - AL13 case generated - AL09 added to AL08 | E13: 3 | G13: Not Started | J13: MHI/ EA | K13: Regression
... A20: AR19 | B20: Child-Non-Bail-Post Release - Curfew only - HDC (SECTON 91) - 3 hours over 2 events for the same curfew period | C20: - create out at start of curfew event - create return home late event after 1 hour and 15 mins - create a left during curfew after 30 mins - create a return home late after 30 mins - create breach pack - check next day the ATV resets | D20: - AL08 case generated - AL09 added to the AL08 - AL10 case generated - AL13 case generated - AL09 is added to the AL10 | E20: 6 | G20: Not Started | J20: MHI/ EA | K20: Regression
A21: AR20 | B21: Alcohol Montioring-AL02/AL104-Confirmed Tamper | C21: - AAMR - Strap Tamper event received(26 - EV_PID_STRAP_TAMPER_COUNT_INCREASED) - AL02 case created - create WOT - devices changed - create Enforcement AL104 case - create breach pack | D21: manually create WOT book off as Confirmed tamper AL104 To be Promtoed from AL02 | E21: 6 | G21: Not Started | H21: 26 - EV_PID_STRAP_TAMPER_COUNT_INCREASED | J21: LJ | K21: Regression
A22: AR21 | B22: Alcohol Monitoring-AL21-Battery Low | C22: - AAMR - PID Low Battery event received(38 - EV_PID_BATTERY_LOW) - AL21 case created - create WOT | D22: manually create Work order task for the AL21 Case | E22: 3 | G22: Not Started | H22: 38 - EV_PID_BATTERY_LOW | J22: LJ | K22: Regression
A23: AR22 | B23: Alcohol Monitoring-AL17-Alcohol threshold breach | C23: - Alcohol Detected event received(430 - EV_ALCOHOL_THRESHOLD_BREACH) - AL17 case created - create breach pack | D23: AL17 Case to generate Breach pack to be generated | E23: 3 | G23: Not Started | H23: 430 - EV_ALCOHOL_THRESHOLD_BREACH | J23: LJ | K23: Regression
A24: AR23 | B24: Alcohol Monitoring-AL24-Replace Equipment | C24: - Replace Equipment event received(441 - EV_REPLACE_EQUIPMENT) - AL24 case created - create WOT | D24: Manually create Work order task for case AL24 | E24: 3 | G24: Not Started | H24: 441 - EV_REPLACE_EQUIPMENT | J24: LJ | K24: Regression
A25: AR24 | B25: Alcohol montioring-AL25-CRITICAL COMMS | C25: - AAMR - Base station has transmited Bracelet data after a critical_comms_period alert event received - 462 CRITICAL COMMS PERIOD TO BE SENT BY SCRAM - AL25 case created - create Breach '- Comms established event received - no other event(463_COMMS_ESTABLISHED) - update AL25 case | D25: 462 Code is deployed -AL25 Generated -breach pack created -463 to end the case and update the AL25 Case | E25: 6 | G25: Not Started | H25: 462 - EV_CRITICAL_COMMS_PERIOD 463_COMMS_ESTABLISHED | J25: LJ | K25: Regression
A26: AR25 | B26: Alcohol montioring-AL26-Potential Tamper | C26: - Confirmed obstruction event received - 440 code for scram to send through - AL26 case created - Notification automatically sent out and case updated to resolved by system | D26: AL26 to sne dout the notification and then Auto reslove | E26: 4 | G26: Not Started | H26: 440 - EV_POTENTIAL_TAMPER | J26: LJ | K26: Regression
A27: AR26 | B27: Alcohol montioring-AL31-Alochol threshold breach at install | C27: 1. Task install visit - COMPLETE INSTALL 2. Scram to generate TAC(461) 3. Check AL31 generated 4. Check notification email sent | D27: Notification auto sent | E27: 4 | G27: Not Started | H27: 461 - EV_ALCOHOL_THRESHOLD_BREACH_TAC_AT_INSTALL | J27: LJ | K27: Regression
A28: AR27 | B28: Bail - Withdrawal of Consent | C28: 1. Create EC 2. Task Visit 3. Task install visit - book off as Withdrawal of consent 4. Create breach | D28: AL102 generated | E28: 4 | G28: Not Started | J28: MHI/ EA | K28: Regression
A29: AR28 | B29: Bail - Threatening or abusive behaviour | C29: 1. Create EC 2. Task Visit 3. Task install visit - book off as Threating or Abusive Behaviour 4. Create breach | D29: AL101 | E29: 4 | G29: Not Started | J29: MHI/ EA | K29: Regression
A30: AR29 | B30: Non-Bail - Withdrawal of consent | C30: 1. Create EC 2. Task Visit 3. Task install visit - book off as Withdrawal of consent 4. Create breach | D30: AL102 generated | E30: 4 | G30: Not Started | J30: MHI/ EA | K30: Regression
A31: AR30 | B31: Bail - Adult - No Show | C31: 1. Create EC 2. Task Visit 3. Task install visit - book off as no show x2 4. Create breach | D31: AL100 generated | E31: 4 | G31: Not Started | J31: MHI/ EA | K31: Regression
A32: AR31 | B32: AM - No Show | C32: 1. Create EC 2. Task Visit 3. Task install visit - book off as no show x3 4. Create breach | D32: AL100 generated | E32: 4 | G32: Not Started | J32: LJ | K32: Regression
A33: AR32 | B33: Bail - Child - No Show | C33: 1. Create EC 2. Task Visit 3. Task install visit - book off as no show 4. Create breach | D33: AL100 generated | E33: 4 | G33: Not Started | J33: MHI/ EA | K33: Regression
A34: AR33 | B34: Bail - Curfew & exclusion - Strap Tamper | C34: 1. Generate strap tamper 2. Update AL03 - confirmed tamper 3 Create visit to comfirm Tamper 4. Book off as confirmed tamper 5. promote manually enforcement to an AL104 6. Create breach 7. State update automatically to awaiting enforcement | D34: AL03 generated AL104 manually Generated after visit | E34: 7 | G34: Not Started | J34: MHI/ EA | K34: Regression
A35: AR34 | B35: Non-bail-Curfew & Exclusion -Strap tamper | C35: 1. Generate tamper 2. AL03-Generated 3. Create visit to comfirm Tamper 4. Book off as confirmed tamper 5. Create breach | D35: AL03 generated AL104 manually Generated after visit | E35: 5 | G35: Not Started | J35: MHI/ EA | K35: Regression
A36: AR35 | B36: Non Bail exclusion only - Strap Tamper | C36: 1. Generate strap tamper 2. Update AL02 3. Create visit to comfirm Tamper 4. Book off as confirmed tamper 5. promote manually enforcement to an AL104 6. Create breach 7. State update automatically to awaiting enforcement | D36: AL02 generated AL104 manually Generated after visit | E36: 7 | G36: Not Started | J36: MHI/ EA | K36: Regression

Sheet Validation
A1: Pass | C1: Open
A2: Fail | C2: Retest
A3: No Run | C3: Ready for Prod
A4: Not Completed | C4: Training
A5: In Progress | C5: Closed
A6: Out of Scope | C6: On Hold
A7: Development
A8: Blocked
A9: Not Started

Sheet Defects
A1: Incident / JIRA ref | B1: Test ID | C1: Issue | D1: Description | E1: Category | F1: Impact Rating (H-M-L) | G1: Date Opened | H1: Date Resolved | I1: Target Release Date | J1: Status | K1: Resolution | L1: Notes
A2: 1
A3: 2
A4: 3
A5: 4
A6: 5
A7: 6
A8: 7
A9: 8
A10: 9
A11: 10
A12: 11
A13: 12
... A100: 99
G1048576: 6.1.25

Sheet Sheet1
B2: Testing Timeline
B5: 19th | E5: 20th | H5: 21st | I5: 24th | J5: 25th | K5: 26th | L5: 27th | M5: 28th
A6: ST | B6: OE44 * Install alcohol kit | D6: ST | E6: DV50 * Asset Manager BPSS persona | G6: ST | H6: DV50 * Asset Manager BPSS persona
A7: KW | B7: DV41 * Field Service Officer persona | D7: ST | E7: DV51 * Asset Manager CTC persona | G7: ST | H7: DV51 * Asset Manager CTC persona
A8: KW | B8: DV42 * Field Service Officer SPECIALS persona | D8: ST | E8: DV21 * Field Service Scheduler BPSS persona | G8: ST | H8: DV21 * Field Service Scheduler BPSS persona
A9: LJ | B9: DV44 * Quality Assurance CTC persona | D9: ST | E9: DV22 * Field Service Scheduler CTC persona | G9: ST | H9: DV22 * Field Service Scheduler CTC persona
A10: EM | B10: DV48 * CMT Immigration persona FAILED | D10: TL / MHI | E10: TA08 * atv breaches | H10: TA31
A11: EM | B11: DV49 * CMT (MoJ) personas PASSED | D11: ST | E11: OEO7 * install following OE01 decom | H11: TA10 / OE70
A12: ST | B12: OE69 * install NFD | D12: EM | E12: TA04 *EXCLUSION | G12: EM | H12: TA04 *EXCLUSION
A13: EM | B13: TA09 / OE69 * start the AL18 process | D13: EM | E13: TA30 *AL15 | G13: EM | H13: TA30 *AL15
A14: TL / MHI | B14: TA01 / OE01 * finish generating the atvs & breach packs | D14: EM | E14: TA47 * AL24 -SPOOF | G14: EM | H14: TA47 * AL24 -SPOOF
A15: TL / MHI | B15: TA52 / OE01 * generate AL04 | D15: LJ | E15: TA48 * AL20 | H15: OE06
A16: ST | B16: TA43 / OE01 * request spoof event from AUEM | D16: LJ | E16: OE04 * check further visit has generated after previous visit booked off as faulty equipment | H16: OE76
A17: ST | B17: OE01 * decom kit once event has been spoofed | D17: ST | E17: OE01 * decom kit | H17: OE08
A18: EM / ST & KW | B18: OE04 * Create order * Assign WOT to Mark * 2x no show visits | D18: ST | E18: OE03 * 2x no show | H18: TA41
A19: ST & KW | B19: OE03 * Assign WOT to Mark * 2x no show visits | D19: TL / MHI | E19: TA02 * 2x no show breach | H19: OE09 | I19: NO SHOW
A20: TL / MHI | B20: TA05 / OE02 * Create multiple exclusions Day 1 | D20: TL / MHI | E20: TA05 / OE02 * Create multiple exclusions Day 2 | H20: OE10 | I20: BOOK OFFS
A21: TL / MHI & ST | B21: TA11 / OE02 * Generate strap tamper * Complete tamper visit | D21: TL / MHI | E21: TA46 * breach | H21: OE15
A22: TL / MHI | B22: TA33 / OE20 * battery dead | D22: ST | E22: TA03 * 2x no show | H22: OE16
A23: MS | B23: OE08 * Create order | D23: TL / MHI | E23: TA03 * breach | H23: OE17
A24: MS | B24: OE09 * Create order | D24: ST | E24: OE11 * 2x no show | H24: OE12
A25: MS | B25: OE10 * Create order | D25: TL / MHI | E25: TA13 * breach | H25: OE13
A26: MS | B26: OE11 * Create order | D26: LJ | E26: TA68 * breach | G26: LJ | H26: TA68 * breach
A27: MS | B27: OE12 * Create order | D27: EM | E27: OE18 * decom
A28: MS | B28: OE13 * Create order | D28: MS | E28: OE15 * create order
A29: CL | B29: OE45 * Create order | D29: MS | E29: OE16 * create order
A30: CL | B30: OE46 * Create order | D30: MS | E30: OE17 * create order
A31: CL | B31: OE47 * Create order | D31: MS | E31: OE19 * create order
A32: ST | B32: OE14 * decom kit | D32: MS | E32: OE21 * create order
A33: ST | B33: OE20 * install kit | D33: MS | E33: OE22 * create order
A34: TL / MHI | B34: TA08 * start atv breaches | D34: MS | E34: OE23 * create order
D35: MS | E35: OE24 * create order
D36: MS | E36: OE25 * create order
D37: MS | E37: OE26 * create order | G37: MS | H37: OE26 * create order
D38: MS | E38: OE27 * create order
D39: MS | E39: OE28 * create order | G39: MS | H39: OE28 * create order
D40: CL | E40: OE29 * create order | G40: MS | H40: OE29 * create order
D41: CL | E41: OE30 * create order | G41: MS | H41: OE30 * create order
D42: CL | E42: OE31 * create order | G42: MS | H42: OE31 * create order
D43: CL | E43: AC01 * create order | G43: CL | H43: AC01 * create order
...

Sheet OVERALL
A1: Test ID | B1: Test Scenario | C1: Test Steps | D1: Outcome Expected | E1: # of Steps | F1: Completed Steps | G1: Status | H1: Notes | I1: Data notes | J1: Tested by | K1: Story
AE12: =COUNTIF('Alert Regression'!$G$2:$G$38,Summary!AC12) -> 0
