Workbook
Name Status: #N/A
Name statuslist: Validation!$A$1:$A$9

Sheet Version Control
C3: Document Information
C4: Title | D4: Test Execution Progress Log
C5: Title | D5: Feb Release - Bail ATV
C6: Release Identifier | D6: RLSE0010196
C7: Author | D7: Beverley Barlow
C9: Document Version History
C10: Version | D10: Date | E10: Summary of Changes
C11: 0.1 | D11: 46027 | E11: Initial Definition of Test Cases
C12: 0.2 | D12: 46053 | E12: Final Copy for MOJ Review
C17: Test Evidence Repository
C18: Test Execution Evidence is stored at this link | E18: Link to Test Evidence Repository
C20: Scope of Release
C21: This release implements a Servicenow upgrade
C22: Defect/Story ID | D22: Type | E22: Details
C23: STRY0084697 | D23: Enhancement | E23: Bail S9 ATV statement when no end event is present
C24: STRY0084698 | D24: Enhancement | E24: Bail S9 ATV statement when end event IS present
C25: STRY0085026 | D25: Enhancement | E25: Bail S9 ATV statement when Out for entire curfew period
C26: STRY0085027 | D26: Enhancement | E26: New field to capture pre-trial threshold met time
C27: STRY0085703 | D27: Enhancement | E27: DAPO S9 ATV statement when end event IS present
C28: STRY0085710 | D28: Enhancement | E28: DAPO S9 ATV statement when no end event present
C29: STRY0085711 | D29: Enhancement | E29: DAPO S9 ATV statement when Out for entire curfew period
C30: STRY0085718 | D30: Enhancement | E30: Ensure Bail S9 packs are generated for MO's under RF/GPS extradition descriptions
C31: STRY0085755 | D31: Enhancement | E31: ATV wording for Immigration bail breach packs

Sheet Summary
E2: ORDERS DASHBOARD | R2: SHEET4 DASHBOARD | AF2: OVERALL DASHBOARD
B4: Execution Progress | O4: Execution Progress | AC4: Execution Progress
B5: Steps Completed | C5: =SUM(ORDERS!F2:F43) -> 137 | O5: Steps Completed | P5: =SUM('Sheet 4'!F2:F41) -> 0 | AC5: Steps Completed | AD5: =SUM(OVERALL!F2:F82) -> 0
B6: Steps Remaining | C6: =C7-C5 -> 0 | O6: Steps Remaining | P6: =SUM(P7-P5) -> 0 | AC6: Steps Remaining | AD6: =SUM(AD7-AD5) -> 0
B7: Total Steps | C7: =SUM(ORDERS!E2:E43) -> 137 | O7: Total Steps | P7: =SUM('Sheet 4'!E2:E41) -> 0 | AC7: Total Steps | AD7: =SUM(OVERALL!E2:E82) -> 0
B9: % Complete | C9: =C5/C7 -> 1 | O9: % Complete | P9: =P5/P7 -> #DIV/0! | AC9: % Complete | AD9: =AD5/AD7 -> #DIV/0!
B11: Script Status | O11: Script Status | AC11: Script Status
B12: Pass | C12: =COUNTIF(ORDERS!$G$2:$G$143,Summary!B12) -> 14 | D12: =C12/$C$19 -> 1 | O12: Pass | P12: =COUNTIF('Sheet 4'!$G$2:$G$148,Summary!O12) -> 0 | Q12: =P12/$P$19 -> #DIV/0! | AC12: Pass | AD12: =COUNTIF(OVERALL!$G$2:$G$150,Summary!AC12) -> 0 | AE12: =AD12/$AD$19 -> #DIV/0!
B13: Fail | C13: =COUNTIF(ORDERS!$G$2:$G$143,Summary!B13) -> 0 | D13: =C13/$C$19 -> 0 | O13: Fail | P13: =COUNTIF('Sheet 4'!$G$2:$G$148,Summary!O13) -> 0 | Q13: =P13/$P$19 -> #DIV/0! | AC13: Fail | AD13: =COUNTIF(OVERALL!$G$2:$G$150,Summary!AC13) -> 0 | AE13: =AD13/$AD$19 -> #DIV/0!
B14: No Run | C14: =COUNTIF(ORDERS!$G$2:$G$143,Summary!B14) -> 0 | D14: =C14/$C$19 -> 0 | O14: No Run | P14: =COUNTIF('Sheet 4'!$G$2:$G$148,Summary!O14) -> 0 | Q14: =P14/$P$19 -> #DIV/0! | AC14: No Run | AD14: =COUNTIF(OVERALL!$G$2:$G$150,Summary!AC14) -> 0 | AE14: =AD14/$AD$19 -> #DIV/0!
B15: Not Completed | C15: =COUNTIF(ORDERS!$G$2:$G$143,Summary!B15) -> 0 | D15: =C15/$C$19 -> 0 | O15: Not Completed | P15: =COUNTIF('Sheet 4'!$G$2:$G$148,Summary!O15) -> 0 | Q15: =P15/$P$19 -> #DIV/0! | AC15: Not Completed | AD15: =COUNTIF(OVERALL!$G$2:$G$150,Summary!AC15) -> 0 | AE15: =AD15/$AD$19 -> #DIV/0!
B16: In Progress | C16: =COUNTIF(ORDERS!$G$2:$G$143,Summary!B16) -> 0 | D16: =C16/$C$19 -> 0 | O16: In Progress | P16: =COUNTIF('Sheet 4'!$G$2:$G$148,Summary!O16) -> 0 | Q16: =P16/$P$19 -> #DIV/0! | AC16: In Progress | AD16: =COUNTIF(OVERALL!$G$2:$G$150,Summary!AC16) -> 0 | AE16: =AD16/$AD$19 -> #DIV/0!
B17: Out of Scope | C17: =COUNTIF(ORDERS!$G$2:$G$143,Summary!B17) -> 0 | D17: =C17/$C$19 -> 0 | O17: Out of Scope | P17: =COUNTIF('Sheet 4'!$G$2:$G$148,Summary!O17) -> 0 | Q17: =P17/$P$19 -> #DIV/0! | AC17: Out of Scope | AD17: =COUNTIF(OVERALL!$G$2:$G$150,Summary!AC17) -> 0 | AE17: =AD17/$AD$19 -> #DIV/0!
B18: Not Started | C18: =COUNTIF(ORDERS!$G$2:$G$143,Summary!B18) -> 0 | D18: =C18/$C$19 -> 0 | O18: Not Started | P18: =COUNTIF('Sheet 4'!$G$2:$G$148,Summary!O18) -> 0 | Q18: =P18/$P$19 -> #DIV/0! | AC18: Not Started | AD18: =COUNTIF(OVERALL!$G$2:$G$150,Summary!AC18) -> 0 | AE18: =AD18/$AD$19 -> #DIV/0!
B19: TOTAL | C19: =SUM(C12:C18) -> 14 | O19: TOTAL | P19: =SUM(P12:P18) -> 0 | AC19: TOTAL | AD19: =SUM(AD12:AD18) -> 0
E23: ACQUISITIVE CRIME DASHBOARD | Q23: BAIL ATV DASHBOARD
B25: Execution Progress | O25: Execution Progress
B26: Steps Completed | C26: =SUM(AcquisitiveCrime!F2:F58) -> 14 | O26: Steps Completed | P26: =SUM('Bail ATV'!F2:F62) -> 101
B27: Steps Remaining | C27: =SUM(C28-C26) -> 0 | O27: Steps Remaining | P27: =P28-P26 -> 0
B28: Total Steps | C28: =SUM(AcquisitiveCrime!E2:E58) -> 14 | O28: Total Steps | P28: =SUM('Bail ATV'!E2:E62) -> 101
B30: % Complete | C30: =C26/C28 -> 1 | O30: % Complete | P30: =P26/P28 -> 1
B32: Script Status | O32: Script Status
B33: Pass | C33: =COUNTIF(AcquisitiveCrime!$G$2:$G$148,Summary!B33) -> 3 | D33: =C33/$C$40 -> 1 | O33: Pass | P33: =COUNTIF('Bail ATV'!$G$2:$G$150,Summary!O33) -> 35 | Q33: =P33/$P$40 -> 0.76086957
B34: Fail | C34: =COUNTIF(AcquisitiveCrime!$G$2:$G$148,Summary!B34) -> 0 | D34: =C34/$C$40 -> 0 | O34: Fail | P34: =COUNTIF('Bail ATV'!$G$2:$G$150,Summary!O34) -> 0 | Q34: =P34/$P$40 -> 0
B35: No Run | C35: =COUNTIF(AcquisitiveCrime!$G$2:$G$148,Summary!B35) -> 0 | D35: =C35/$C$40 -> 0 | O35: No Run | P35: =COUNTIF('Bail ATV'!$G$2:$G$150,Summary!O35) -> 0 | Q35: =P35/$P$40 -> 0
B36: Not Completed | C36: =COUNTIF(AcquisitiveCrime!$G$2:$G$148,Summary!B36) -> 0 | D36: =C36/$C$40 -> 0 | O36: Not Completed | P36: =COUNTIF('Bail ATV'!$G$2:$G$150,Summary!O36) -> 0 | Q36: =P36/$P$40 -> 0
B37: In Progress | C37: =COUNTIF(AcquisitiveCrime!$G$2:$G$148,Summary!B37) -> 0 | D37: =C37/$C$40 -> 0 | O37: In Progress | P37: =COUNTIF('Bail ATV'!$G$2:$G$150,Summary!O37) -> 0 | Q37: =P37/$P$40 -> 0
B38: Out of Scope | C38: =COUNTIF(AcquisitiveCrime!$G$2:$G$148,Summary!B38) -> 0 | D38: =C38/$C$40 -> 0 | O38: Out of Scope | P38: =COUNTIF('Bail ATV'!$G$2:$G$150,Summary!O38) -> 11 | Q38: =P38/$P$40 -> 0.23913043
B39: Not Started | C39: =COUNTIF(AcquisitiveCrime!$G$2:$G$148,Summary!B39) -> 0 | D39: =C39/$C$40 -> 0 | O39: Not Started | P39: =COUNTIF('Bail ATV'!$G$2:$G$150,Summary!O39) -> 0 | Q39: =P39/$P$40 -> 0
B40: TOTAL | C40: =SUM(C33:C39) -> 3 | O40: TOTAL | P40: =SUM(P33:P39) -> 46

Sheet ORDERS
A1: Test ID | B1: Test Scenario | C1: Test Steps | D1: Outcome Expected | E1: # of Steps | F1: Completed Steps | G1: Status | H1: Notes | I1: Test Data Used | J1: Tests
A2: BC01 | B2: Adult - New Order - Verified Address - RF Bail-Curfew only | C2: 1. create Interaction 2. create Contact 3. create Device Wearer 4. create Case 5. create Monitoring Order 6. create Monitoring Requirements 7. create Monitoring Configuration 8. create Work Order 9. Create Work Order Task 10. Install | D2: - interaction, case, mon order, work order and work order task created | E2: 10 | F2: 10 | G2: Pass | H2: defects on the interaction DFCT0011478 - defect did not halt the order creation | I2: DEVWR0101629 / MON10119176 | J2: BA01 BA02 BA03 BA04 BA21 BA33
A3: BC02 | B3: Adult-Non-Bail-Community-curfew | C3: 1. create Interaction 2. create Contact 3. create Device Wearer 4. create Case 5. create Monitoring Order 6. create Monitoring Requirements 7. create Monitoring Configuration 8. create Work Order 9. Create Work Order Task 10. Install | D3: - interaction, case, mon order, work order and work order task created | E3: 10 | F3: 10 | G3: Pass | H3: defects on the interaction DFCT0011478 - defect did not halt the order creation | I3: DEVWR0101633 / MON10119178 | J3: BA05 BA06 BA07 BA08 BA22 BA34
A4: BC03 | B4: Immigration-GPS | C4: 1. create Interaction 2. create Contact 3. create Device Wearer 4. create Case 5. create Monitoring Order 6. create Monitoring Requirements 7. create Monitoring Configuration 8. create Work Order 9. Create Work Order Task 10. Install | D4: - interaction, case, mon order, work order and work order task created | E4: 10 | F4: 10 | G4: Pass | I4: DEVWR0101642 / MON10119180 | J4: BA09 BA10 BA11 BA12 BA23 BA37
A5: BC04 | B5: DAPO | C5: 1. create Interaction 2. create Contact 3. create Device Wearer 4. create Case 5. create Monitoring Order 6. create Monitoring Requirements 7. create Monitoring Configuration 8. create Work Order 9. Create Work Order Task 10. Install | D5: - interaction, case, mon order, work order and work order task created | E5: 10 | F5: 10 | G5: Pass | I5: DEVWR0101648 / MON10119183 | J5: BA13 BA14 BA15 BA16 BA24
A6: BC05 | B6: Bail-RF Extradition | C6: 1. create Interaction 2. create Contact 3. create Device Wearer 4. create Case 5. create Monitoring Order 6. create Monitoring Requirements 7. create Monitoring Configuration 8. create Work Order 9. Create Work Order Task 10. Install | D6: - interaction, case, mon order, work order and work order task created | E6: 10 | F6: 10 | G6: Pass | I6: DEVWR0101650 / MON10119184 | J6: BA17 BA18
A7: BC06 | B7: Bail-GPS-Extradition | C7: 1. create Interaction 2. create Contact 3. create Device Wearer 4. create Case 5. create Monitoring Order 6. create Monitoring Requirements 7. create Monitoring Configuration 8. create Work Order 9. Create Work Order Task 10. Install | D7: - interaction, case, mon order, work order and work order task created | E7: 10 | F7: 10 | G7: Pass | I7: DEVWR0101655 / MON10119189 | J7: BA19 BA20
A8: BC07 | B8: Adult-Bail-Curfew and exculsion | C8: 1. create Interaction 2. create Contact 3. create Device Wearer 4. create Case 5. create Monitoring Order 6. create Monitoring Requirements 7. create Monitoring Configuration 8. create Work Order 9. Create Work Order Task 10. Install | D8: - interaction, case, mon order, work order and work order task created | E8: 10 | F8: 10 | G8: Pass | I8: DEVWR0101657 / MON10119190 | J8: BA25 BA27
A9: BC08 | B9: Adult-Non-Bail-Curfew and exculsion | C9: 1. create Interaction 2. create Contact 3. create Device Wearer 4. create Case 5. create Monitoring Order 6. create Monitoring Requirements 7. create Monitoring Configuration 8. create Work Order 9. Create Work Order Task 10. Install | D9: - interaction, case, mon order, work order and work order task created | E9: 10 | F9: 10 | G9: Pass | I9: DEVWR0101659 / MON10119191 | J9: BA26 BA28
A10: BC09 | B10: Adult - New Order - Verified Address - RF Bail-Curfew only | C10: 1. create Interaction 2. create Contact 3. create Device Wearer 4. create Case 5. create Monitoring Order 6. create Monitoring Requirements 7. create Monitoring Configuration 8. create Work Order 9. Create Work Order Task | D10: - interaction, case, mon order, work order and work order task created | E10: 9 | F10: 9 | G10: Pass | I10: MON10119194/ DEVWR0101662 | J10: BA29 BA31
A11: BC10 | B11: Adult-Non-Bail-Community-curfew | C11: 1. create Interaction 2. create Contact 3. create Device Wearer 4. create Case 5. create Monitoring Order 6. create Monitoring Requirements 7. create Monitoring Configuration 8. create Work Order 9. Create Work Order Task | D11: - interaction, case, mon order, work order and work order task created | E11: 9 | F11: 9 | G11: Pass | I11: DEVWR0101665/ MON10119196 | J11: BA30 BA32
A12: BC11 | B12: Immigration-GPS | C12: 1. create Interaction 2. create Contact 3. create Device Wearer 4. create Case 5. create Monitoring Order 6. create Monitoring Requirements 7. create Monitoring Configuration 8. create Work Order 9. Create Work Order Task | D12: - interaction, case, mon order, work order and work order task created | E12: 9 | F12: 9 | G12: Pass | I12: DEVWR0101667/ MON10119197 | J12: BA35 BA36
A13: BC12 | B13: Child - New Order - Verified Address - RF Bail-Curfew only | C13: 1. create Interaction 2. create Contact 3. create Device Wearer 4. create Case 5. create Monitoring Order 6. create Monitoring Requirements 7. create Monitoring Configuration 8. create Work Order 9. Create Work Order Task 10. Install | D13: - interaction, case, mon order, work order and work order task created | E13: 10 | F13: 10 | G13: Pass | I13: DEVWR0101671/ MON10119199 | J13: BA38 BA39 BA40 BA41
A14: BC13 | B14: Child-Non-Bail-Post Release - HDC (SECTON 91) | C14: 1. create Interaction 2. create Contact 3. create Device Wearer 4. create Case 5. create Monitoring Order 6. create Monitoring Requirements 7. create Monitoring Configuration 8. create Work Order 9. Create Work Order Task 10. Install | D14: - interaction, case, mon order, work order and work order task created | E14: 10 | F14: 10 | G14: Pass | I14: DEVWR0101644/ MON10119181 | J14: BA42 BA43 BA44 BA45
A15: BC14 | B15: Immigration-NFD | C15: 1. create Interaction 2. create Contact 3. create Device Wearer 4. create Case 5. create Monitoring Order 6. create Monitoring Requirements 7. create Monitoring Configuration 8. create Work Order 9. Create Work Order Task 10. Install | D15: - interaction, case, mon order, work order and work order task created | E15: 10 | F15: 10 | G15: Pass | I15: DEVWR0101774 / MON10119302 | J15: BA46
SX78: Column1

Sheet Bail ATV
A1: Test ID | B1: Test Scenario | C1: Test Steps | D1: Outcome Expected | E1: # of Steps | F1: Completed Steps | G1: Status | H1: Notes | I1: Data notes
A2: BA01 | B2: Bail - GPS - ATV | C2: 15 min in 1 event for same curfew period - create breach pack | D2: AL08/AL10 case generated followed by AL13 case generated | E2: 2 | F2: 2 | G2: Pass | I2: BC01
A3: BA02 | B3: Bail - GPS - ATV | C3: 15 min over 2 or 3 events for same curfew period - create breach pack | D3: AL08/AL10 case generated followed by AL13 case generated | E3: 2 | F3: 2 | G3: Pass | H3: For example: DW curfew 10am - 2pm Violation 1 - 10.10.00 - 10.15.30 Duration = 5 mins 30 seconds Violation 2 - 10.30.00 - 10.38.15 Duration = 8 mins 15 seconds Violation 3 - 11.02.00 - DW still out when 15 mins reached Remaining time left from the 15 min duration: 15 min - 5 min 30 seconds - 8 mins 15 seconds = 1 minute 15 seconds ATV threshold met = 11.02.00 + 1 min 15 seconds = 05/12/2025 11:03:15 | I3: BC01
A4: BA03 | B4: Bail - GPS - ATV | C4: 15 min over 2 or 3 events - over 2 curfew periods | D4: AL08/AL10 case generated | E4: 1 | F4: 1 | G4: Pass | I4: BC01
A5: BA04 | B5: Bail - GPS - ATV | C5: 15 min in 1 event for same curfew period - create breach pack before return | D5: AL08/AL10 case generated followed by AL13 case generated | E5: 2 | F5: 2 | G5: Pass | I5: BC01
A6: BA05 | B6: Non-Bail - GPS - ATV | C6: 2 hours in 1 event for same curfew period | D6: AL08/AL10 case generated followed by AL13 case generated | E6: 2 | F6: 2 | G6: Pass | I6: BC02
A7: BA06 | B7: Non-Bail - GPS - ATV | C7: 2 hours over 2 or 3 events for same curfew period | D7: AL08/AL10 case generated followed by AL13 case generated | E7: 2 | F7: 2 | G7: Pass | H7: "For example: DW curfew 10am - 2pm Violation 1 - 10.10.00 - 11.15.30 Duration = 1 hour 5 mins 30 seconds Violation 2 - 11:30:00 - 11:58:15 Duration = 28 mins 15 seconds Violation 3 - 12.02.00 - DW still out when 2 hours reached Remaining time left from the 2 hours duration: 15 min - 1 hour 5 min 30 seconds - 28 mins 15 seconds = 26 minute 15 seconds ATV threshold met = 12.02.00 + 26 min 15 seconds = 05/12/2025 12:28:15" | I7: BC02
A8: BA07 | B8: Non-Bail - GPS - ATV | C8: 2 hours over 2 or 3 events - over 2 curfew periods | D8: AL08/AL10 case generated | E8: 1 | F8: 1 | G8: Pass | I8: BC02
A9: BA08 | B9: Non-Bail - GPS - ATV | C9: 2 Hours in 1 event for same curfew period - create breach pack before return | D9: AL08/AL10 case generated followed by AL13 case generated | E9: 2 | F9: 2 | G9: Out of Scope | H9: Non-bail aggregates time breaches based on start/end periods on AL08 and AL10 - this is not a valid test | I9: BC02
A10: BA09 | B10: Immigration-GPS-ATV | C10: 2 hours in 1 event for same curfew period | D10: AL08/AL10 case generated followed by AL13 case generated | E10: 2 | F10: 2 | G10: Out of Scope | H10: 'Currently not getting curfew orders | I10: BC03
A11: BA10 | B11: Immigration-GPS-ATV | C11: 2 hours over 2 or 3 events for same curfew period | D11: AL08/AL10 case generated followed by AL13 case generated | E11: 2 | F11: 2 | G11: Out of Scope | H11: 'Currently not getting curfew orders | I11: BC03
A12: BA11 | B12: Immigration-GPS-ATV | C12: 2 hours over 2 or 3 events - over 2 curfew periods | D12: AL08/AL10 case generated | E12: 1 | F12: 1 | G12: Out of Scope | H12: 'Currently not getting curfew orders | I12: BC03
A13: BA12 | B13: Immigration-GPS-ATV | C13: 2 Hours in 1 event for same curfew period - create breach pack before return | D13: AL08/AL10 case generated followed by AL13 case generated | E13: 2 | F13: 2 | G13: Out of Scope | H13: 'Currently not getting curfew orders | I13: BC03
A14: BA13 | B14: DAPO - RF - ATV | C14: 15 min in 1 event for same curfew period - create breach pack | D14: AL08/AL10 case generated followed by AL13 case generated | E14: 2 | F14: 2 | G14: Pass | H14: Passed evidence attached | I14: BC04
A15: BA14 | B15: DAPO - RF - ATV | C15: 15 min over 2 or 3 events for same curfew period - create breach pack 15 min over 2 events in same curfew - device not returned create breach pack | D15: AL08/AL10 case generated followed by AL13 case generated | E15: 2 | F15: 2 | G15: Pass | H15: For example: DW curfew 10am - 2pm Violation 1 - 10.10.00 - 10.15.30 Duration = 5 mins 30 seconds Violation 2 - 10.30.00 - 10.38.15 Duration = 8 mins 15 seconds Violation 3 - 11.02.00 - DW still out when 15 mins reached Remaining time left from the 15 min duration: 15 min - 5 min 30 seconds - 8 mins 15 seconds = 1 minute 15 seconds ATV threshold met = 11.02.00 + 1 min 15 seconds = 05/12/2025 11:03:15 | I15: BC04
A16: BA15 | B16: DAPO - RF - ATV | C16: 15 min over 2 or 3 events - over 2 curfew periods | D16: AL08/AL10 case generated | E16: 1 | F16: 1 | G16: Pass | I16: BC04
A17: BA16 | B17: DAPO - RF - ATV | C17: 15 min in 1 event for same curfew period - create breach pack before return | D17: AL08/AL10 case generated followed by AL13 case generated | E17: 2 | F17: 2 | G17: Pass | I17: BC04
A18: BA17 | B18: Bail-RF Extradition | C18: 15 min in 1 event for same curfew period - create breach pack | D18: AL08/AL10 case generated followed by AL13 case generated | E18: 2 | F18: 2 | G18: Pass | I18: BC05
A19: BA18 | B19: Bail-RF Extradition | C19: 15 min over 2 or 3 events for same curfew period - create breach pack | D19: AL08/AL10 case generated followed by AL13 case generated | E19: 2 | F19: 2 | G19: Pass | H19: "For example: DW curfew 10am - 2pm Violation 1 - 10.10.00 - 10.15.30 Duration = 5 mins 30 seconds Violation 2 - 10.30.00 - 10.38.15 Duration = 8 mins 15 seconds Violation 3 - 11.02.00 - DW still out when 15 mins reached Remaining time left from the 15 min duration: 15 min - 5 min 30 seconds - 8 mins 15 seconds = 1 minute 15 seconds ATV threshold met = 11.02.00 + 1 min 15 seconds = 05/12/2025 11:03:15" | I19: BC05
A20: BA19 | B20: Bail-GPS Extradition | C20: 15 min in 1 event for same curfew period - create breach pack | D20: AL08/AL10 case generated followed by AL13 case generated | E20: 2 | F20: 2 | G20: Pass | I20: BC06
A21: BA20 | B21: Bail-GPS Extradition | C21: 15 min over 2 or 3 events for same curfew period - create breach pack | D21: AL08/AL10 case generated followed by AL13 case generated | E21: 2 | F21: 2 | G21: Pass | H21: "For example: DW curfew 10am - 2pm Violation 1 - 10.10.00 - 10.15.30 Duration = 5 mins 30 seconds Violation 2 - 10.30.00 - 10.38.15 Duration = 8 mins 15 seconds Violation 3 - 11.02.00 - DW still out when 15 mins reached Remaining time left from the 15 min duration: 15 min - 5 min 30 seconds - 8 mins 15 seconds = 1 minute 15 seconds ATV threshold met = 11.02.00 + 1 min 15 seconds = 05/12/2025 11:03:15" | I21: BC06
A22: BA21 | B22: Bail - RF - ATV | C22: Out for whole curfew | D22: AL08 to generated followed by AL12 | E22: 1 | F22: 1 | G22: Out of Scope | H22: No event for whole curfew - triggered from full period of breach. As breach occurs after 15 mins regardless of whether end event received - not applicable | I22: BC01
A23: BA22 | B23: Non-Bail - GPS - ATV | C23: Out for whole curfew | D23: AL08 to generated followed by AL12 | E23: 1 | F23: 1 | G23: Pass | I23: BC02
A24: BA23 | B24: Immigration-GPS-ATV | C24: Out for whole curfew | D24: AL08 to generated followed by AL12 | E24: 1 | F24: 1 | G24: Out of Scope | H24: 'Currently not getting curfew orders | I24: BC03
A25: BA24 | B25: DAPO - RF - ATV | C25: Out for whole curfew | D25: AL08 to generated followed by AL12 | E25: 1 | F25: 1 | G25: Out of Scope | H25: No event for whole curfew - triggered from full period of breach. As breach occurs after 15 mins regardless of whether end event received - not applicable | I25: BC04
A26: BA25 | B26: Bail-GPS-Curfew & Exclusion | C26: Create exclusion breach AL06 Generated breach pack generated after 7 am | D26: 1 case generated 7am - 6.59am | E26: 3 | F26: 3 | G26: Pass | I26: BC07
A27: BA26 | B27: Non-Bail - GPS-Curfew & Exclusion | C27: Create exclusion breach AL06 Generated breach pack generated after 7 am | D27: 1 case generated 7am - 6.59am | E27: 3 | F27: 3 | G27: Pass | I27: MON10119168
A28: BA27 | B28: Bail - RF - ATV | C28: - create strap tamper AL03 Will Generate - create visit to confirm Tamper visited booked off as confirmed tamper manully protmote to AL104 | D28: - AL03 case generated - AL104 manually Generated after visit | E28: 5 | F28: 5 | G28: Pass | I28: BC07
A29: BA28 | B29: Non-Bail - GPS-Curfew & Exclusion | C29: "- create strap tamper AL03 Will Generate - create visit to confirm Tamper visited booked off as confirmed tamper manully protmote to AL104" | D29: - AL03 case generated - AL104 manually Generated after visit | E29: 5 | F29: 5 | G29: Out of Scope | H29: duplicate of BA26 | I29: BC08
A30: BA29 | B30: Bail - RF - ATV | C30: 1. Task install visit - book off as no show 2. Task 2nd attempt visit - book off as no show 3. Create breach pack | D30: AL100 generated | E30: 3 | F30: 3 | G30: Pass | H30: 2x no show done | I30: BC09
A31: BA30 | B31: Non-Bail - GPS - ATV | C31: 1. Task install visit - book off as no show 2. Task 2nd attempt visit - book off as no show 3. Create breach pack | D31: AL100 to be generated | E31: 3 | F31: 3 | G31: Pass | H31: 2x no show done | I31: BC10
A32: BA31 | B32: Bail - RF - ATV | C32: 1. Task install visit - book off as WOC 2. Create breach pack | D32: AL102 generated | E32: 2 | F32: 2 | G32: Pass | I32: BC09
A33: BA32 | B33: Non-Bail - GPS - ATV | C33: 1. Task install visit - book off as WOC 2. Create breach pack | D33: AL102 generated | E33: 2 | F33: 2 | G33: Pass | I33: BC10
A34: BA33 | B34: Bail - RF - ATV | C34: 1. Generate tamper 2.AL03-Generated, create visit to comfirm Tamper 3. Book off as confirmed tamper 4. Create breach | D34: AL104 manually Generated after visit | E34: 4 | F34: 4 | G34: Out of Scope | H34: duplicate of BA27 | I34: BC01
A35: BA34 | B35: Non-Bail - GPS - ATV | C35: 1. Generate tamper 2.AL03-Generated, create visit to comfirm Tamper 3. Book off as confirmed tamper 4. Create breach | D35: AL104 manually Generated after visit | E35: 4 | F35: 4 | G35: Pass | I35: BC02
A36: BA35 | B36: Immigration-GPS-ATV | C36: 1. Task install visit - book off as no show 2. Task 2nd attempt visit - book off as no show 3. Create breach pack | D36: AL100 generated | E36: 3 | F36: 3 | G36: Pass | H36: 2x no show done | I36: BC11
A37: BA36 | B37: Immigration-GPS-WOC | C37: 1. Task install visit - book off as WOC 2. Create breach pack | D37: AL102 generated | E37: 2 | F37: 2 | G37: Pass | H37: QK AND KL from Immigration signed off on breach pack | I37: BC11
A38: BA37 | B38: Immigration-GPS-ATV (TAMPER & EXCLUSION) | C38: 1. Generate tamper 2.AL02-Generated 3. Create visit to comfirm Tamper 4. Book off as confirmed tamper 5. Create breach | D38: AL104 manually Generated after visit | E38: 5 | F38: 5 | G38: Pass | H38: confirmed with Immigration team | I38: BC03
A39: BA38 | B39: Bail - RF - ATV-Child | C39: 15 min in 1 event for same curfew period - create breach pack | D39: AL08/AL10 case generated followed by AL13 case generated | E39: 2 | F39: 2 | G39: Pass | I39: BC12
A40: BA39 | B40: Bail - RF - ATV-Child | C40: 15 min over 2 or 3 events for same curfew period - create breach pack | D40: AL08/AL10 case generated followed by AL13 case generated | E40: 2 | F40: 2 | G40: Pass | H40: For example: DW curfew 10am - 2pm Violation 1 - 10.10.00 - 10.15.30 Duration = 5 mins 30 seconds Violation 2 - 10.30.00 - 10.38.15 Duration = 8 mins 15 seconds Violation 3 - 11.02.00 - DW still out when 15 mins reached Remaining time left from the 15 min duration: 15 min - 5 min 30 seconds - 8 mins 15 seconds = 1 minute 15 seconds ATV threshold met = 11.02.00 + 1 min 15 seconds = 05/12/2025 11:03:15 | I40: BC12
...

Sheet AcquisitiveCrime
A1: Test ID | B1: Test Scenario | C1: Test Steps | D1: Outcome Expected | E1: # of Steps | F1: Completed Steps | G1: Status | H1: Notes | I1: Test Data Used
A2: BB01 | B2: Adult/New Order/Verified address/GPS Acquisitive Crime Parole/Curfew & Exclsuion | C2: 1. create Interaction 2. create Contact 3. create Device Wearer 4. create Case 5. create Monitoring Order 6. create Monitoring Requirements 7. create Monitoring Configuration 8. create Work Order 9. create Work Order Task 10. install solo and hmu | D2: - interaction, case, mon order, work order and work order task created - devices installed, mon order live | E2: 10 | F2: 10 | G2: Pass | I2: MON10119242 / DEVWR0101728
A3: BB02 | B3: AC-ATV | C3: 2 hours in 1 event for same curfew period al08 will generate al13 will generate create enforcement action | D3: AL08/AL10 case generated followed by AL13 case generated | E3: 1 | F3: 1 | G3: Pass | I3: Follow on from BB01
A4: BB03 | B4: AC-GPS-EXCLSUION | C4: Create exclusion breach AL06 Generated breach pack generated create enforcement action | D4: 1 case generated 7am - 6.59am | E4: 3 | F4: 3 | G4: Pass | I4: Follow on from BB02

Sheet Sheet 4
A1: Test ID | B1: Test Scenario | C1: Test Steps | D1: Outcome Expected | E1: # of Steps | F1: Completed Steps | G1: Status | H1: Notes | I1: Test Data Used | J1: Executed By | K1: Approved By

Sheet Validation
A1: Pass
A2: Fail
A3: No Run
A4: Not Completed
A5: In Progress
A6: Out of Scope
A7: Development
A8: Blocked
A9: Not Started

Sheet Defects
A1: Incident / JIRA ref | B1: Test ID | C1: Issue | D1: Description | E1: Category | F1: Impact Rating (H-M-L) | G1: Date Opened | H1: Date Resolved | I1: Target Release Date | J1: Status | K1: Post Production Check Y/N | L1: Resolution | M1: Release | N1: Notes
A2: 1 | C2: create a decom - no names displaying on a case | G2: 46041 | H2: 19/01/2026 | J2: Closed Complete | K2: N | L2: test data issue | N2: DFCT0011517
A3: 2 | B3: BA14 | C3: Exhibit 06 being in the Breach document when it shouldn’t be there | D3: PE/06 only seems to be appearing for DAPO notifications - PE/06 does not appear in standard bail notifications | G3: 19/01/2026 | H3: 23/01/2026 | J3: Ready for Prod | K3: N | L3: retested | N3: DFCT0011522
A4: 3 | B4: BA14 | C4: 15 minute threshold not showing correct time and instead showing Not available | D4: 15 minute threshold not calculating for multiple atvs - seems to be occurring on DAPO only | G4: 19/01/2026 | H4: 46053 | J4: Ready for Prod | K4: N | L4: retested | N4: DFCT0011523
A5: 4
A6: 5
A7: 6
A8: 7
A9: 8
A10: 9
A11: 10
A12: 11
A13: 12
A14: 13
A15: 14
A16: 15
... A100: 99
G1048576: 6.1.25

Sheet Sheet1
B2: Testing Timeline
B5: 19th | E5: 20th | H5: 21st | I5: 24th | J5: 25th | K5: 26th | L5: 27th | M5: 28th
A6: ST | B6: OE44 * Install alcohol kit | D6: ST | E6: DV50 * Asset Manager BPSS persona | G6: ST | H6: DV50 * Asset Manager BPSS persona
A7: KW | B7: DV41 * Field Service Officer persona | D7: ST | E7: DV51 * Asset Manager CTC persona | G7: ST | H7: DV51 * Asset Manager CTC persona
A8: KW | B8: DV42 * Field Service Officer SPECIALS persona | D8: ST | E8: DV21 * Field Service Scheduler BPSS persona | G8: ST | H8: DV21 * Field Service Scheduler BPSS persona
A9: LJ | B9: DV44 * Quality Assurance CTC persona | D9: ST | E9: DV22 * Field Service Scheduler CTC persona | G9: ST | H9: DV22 * Field Service Scheduler CTC persona
A10: EM | B10: DV48 * CMT Immigration persona FAILED | D10: TL / MHI | E10: TA08 * atv breaches | H10: TA31
A11: EM | B11: DV49 * CMT (MoJ) personas PASSED | D11: ST | E11: OEO7 * install following OE01 decom | H11: TA10 / OE70
A12: ST | B12: OE69 * install NFD | D12: EM | E12: TA04 *EXCLUSION | G12: EM | H12: TA04 *EXCLUSION
A13: EM | B13: TA09 / OE69 * start the AL18 process | D13: EM | E13: TA30 *AL15 | G13: EM | H13: TA30 *AL15
A14: TL / MHI | B14: TA01 / OE01 * finish generating the atvs & breach packs | D14: EM | E14: TA47 * AL24 -SPOOF | G14: EM | H14: TA47 * AL24 -SPOOF
A15: TL / MHI | B15: TA52 / OE01 * generate AL04 | D15: LJ | E15: TA48 * AL20 | H15: OE06
A16: ST | B16: TA43 / OE01 * request spoof event from AUEM | D16: LJ | E16: OE04 * check further visit has generated after previous visit booked off as faulty equipment | H16: OE76
A17: ST | B17: OE01 * decom kit once event has been spoofed | D17: ST | E17: OE01 * decom kit | H17: OE08
A18: EM / ST & KW | B18: OE04 * Create order * Assign WOT to Mark * 2x no show visits | D18: ST | E18: OE03 * 2x no show | H18: TA41
A19: ST & KW | B19: OE03 * Assign WOT to Mark * 2x no show visits | D19: TL / MHI | E19: TA02 * 2x no show breach | H19: OE09 | I19: NO SHOW
A20: TL / MHI | B20: TA05 / OE02 * Create multiple exclusions Day 1 | D20: TL / MHI | E20: TA05 / OE02 * Create multiple exclusions Day 2 | H20: OE10 | I20: BOOK OFFS
A21: TL / MHI & ST | B21: TA11 / OE02 * Generate strap tamper * Complete tamper visit | D21: TL / MHI | E21: TA46 * breach | H21: OE15
A22: TL / MHI | B22: TA33 / OE20 * battery dead | D22: ST | E22: TA03 * 2x no show | H22: OE16
A23: MS | B23: OE08 * Create order | D23: TL / MHI | E23: TA03 * breach | H23: OE17
A24: MS | B24: OE09 * Create order | D24: ST | E24: OE11 * 2x no show | H24: OE12
A25: MS | B25: OE10 * Create order | D25: TL / MHI | E25: TA13 * breach | H25: OE13
A26: MS | B26: OE11 * Create order | D26: LJ | E26: TA68 * breach | G26: LJ | H26: TA68 * breach
A27: MS | B27: OE12 * Create order | D27: EM | E27: OE18 * decom
A28: MS | B28: OE13 * Create order | D28: MS | E28: OE15 * create order
A29: CL | B29: OE45 * Create order | D29: MS | E29: OE16 * create order
A30: CL | B30: OE46 * Create order | D30: MS | E30: OE17 * create order
A31: CL | B31: OE47 * Create order | D31: MS | E31: OE19 * create order
A32: ST | B32: OE14 * decom kit | D32: MS | E32: OE21 * create order
A33: ST | B33: OE20 * install kit | D33: MS | E33: OE22 * create order
A34: TL / MHI | B34: TA08 * start atv breaches | D34: MS | E34: OE23 * create order
D35: MS | E35: OE24 * create order
D36: MS | E36: OE25 * create order
D37: MS | E37: OE26 * create order | G37: MS | H37: OE26 * create order
D38: MS | E38: OE27 * create order
D39: MS | E39: OE28 * create order | G39: MS | H39: OE28 * create order
D40: CL | E40: OE29 * create order | G40: MS | H40: OE29 * create order
D41: CL | E41: OE30 * create order | G41: MS | H41: OE30 * create order
D42: CL | E42: OE31 * create order | G42: MS | H42: OE31 * create order
D43: CL | E43: AC01 * create order | G43: CL | H43: AC01 * create order
...

Sheet OVERALL
A1: Test ID | B1: Test Scenario | C1: Test Steps | D1: Outcome Expected | E1: # of Steps | F1: Completed Steps | G1: Status | H1: Notes | I1: Issue/Defect | J1: SERCO JIRA ID | K1: SNOW defect ID | L1: Approved By
AF12: =COUNTIF('Sheet 4'!$G$2:$G$41,Summary!AC12) -> 0
