Workbook
Name Status: #N/A
Name statuslist: Validation!$A$1:$A$9

Sheet Version Control
C4: Document Information
C5: Title | D5: Test Execution Progress Log
C6: Title | D6: Feb Release - KPI6 & KPI9
C7: Release Identifier | D7: RLSE0010173
C8: Author | D8: Beverley Barlow
C10: Document Version History
C11: Version | D11: Date | E11: Summary of Changes
C12: 0.1 | D12: 46143 | E12: Initial Definition of Test Cases
C13: 0.2 | D13: 46053 | E13: Final Issue for MOJ review
C18: Test Evidence Repository
C19: Test Execution Evidence is stored at this link | E19: Link to Test Evidence Repository
C21: Scope of Release
C22: This release implements a Servicenow upgrade
C23: Defect/Story ID | D23: Type | E23: Details
C24: STRY0084586 | D24: Enhancement | E24: New field to be added on the Interaction Import table, to accurately record the right time / date of the call being made.
C25: STRY0085055 | D25: Enhancement | E25: KPI 6 call made field and the first response time field will be populated with the data in the call_date_time field from the Interaction import table
C26: STRY0085783 | D26: Enhancement | E26: Interaction Import record should not raise an interaction if state = Not Answered
C27: STRY0086362 | D27: Enhancement | E27: Breach pack sent to RO to become mandatory
C28: STRY0086547 | D28: Enhancement | E28: Hiding the propose solution UI action on enforcement cases

Sheet Summary
E2: ORDERS DASHBOARD | R2: SHEET4 DASHBOARD | AF2: OVERALL DASHBOARD
B4: Execution Progress | O4: Execution Progress | AC4: Execution Progress
B5: Steps Completed | C5: =SUM(Orders!F2:F43) -> 90 | O5: Steps Completed | P5: =SUM('Sheet 4'!F2:F41) -> 0 | AC5: Steps Completed | AD5: =SUM(OVERALL!F2:F82) -> 0
B6: Steps Remaining | C6: =C7-C5 -> 0 | O6: Steps Remaining | P6: =SUM(P7-P5) -> 0 | AC6: Steps Remaining | AD6: =SUM(AD7-AD5) -> 0
B7: Total Steps | C7: =SUM(Orders!E2:E43) -> 90 | O7: Total Steps | P7: =SUM('Sheet 4'!E2:E41) -> 0 | AC7: Total Steps | AD7: =SUM(OVERALL!E2:E82) -> 0
B9: % Complete | C9: =C5/C7 -> 1 | O9: % Complete | P9: {=Orders!A2:A10P5/P7} -> #NAME? | AC9: % Complete | AD9: =AD5/AD7 -> #DIV/0!
B11: Script Status | O11: Script Status | AC11: Script Status
B12: Pass | C12: =COUNTIF(Orders!$G$2:$G$143,Summary!B12) -> 9 | D12: =C12/$C$19 -> 1 | O12: Pass | P12: =COUNTIF('Sheet 4'!$G$2:$G$148,Summary!O12) -> 0 | Q12: =P12/$P$19 -> #DIV/0! | AC12: Pass | AD12: =COUNTIF(OVERALL!$G$2:$G$150,Summary!AC12) -> 0 | AE12: =AD12/$AD$19 -> #DIV/0!
B13: Fail | C13: =COUNTIF(Orders!$G$2:$G$143,Summary!B13) -> 0 | D13: =C13/$C$19 -> 0 | O13: Fail | P13: =COUNTIF('Sheet 4'!$G$2:$G$148,Summary!O13) -> 0 | Q13: =P13/$P$19 -> #DIV/0! | AC13: Fail | AD13: =COUNTIF(OVERALL!$G$2:$G$150,Summary!AC13) -> 0 | AE13: =AD13/$AD$19 -> #DIV/0!
B14: No Run | C14: =COUNTIF(Orders!$G$2:$G$143,Summary!B14) -> 0 | D14: =C14/$C$19 -> 0 | O14: No Run | P14: =COUNTIF('Sheet 4'!$G$2:$G$148,Summary!O14) -> 0 | Q14: =P14/$P$19 -> #DIV/0! | AC14: No Run | AD14: =COUNTIF(OVERALL!$G$2:$G$150,Summary!AC14) -> 0 | AE14: =AD14/$AD$19 -> #DIV/0!
B15: Not Completed | C15: =COUNTIF(Orders!$G$2:$G$143,Summary!B15) -> 0 | D15: =C15/$C$19 -> 0 | O15: Not Completed | P15: =COUNTIF('Sheet 4'!$G$2:$G$148,Summary!O15) -> 0 | Q15: =P15/$P$19 -> #DIV/0! | AC15: Not Completed | AD15: =COUNTIF(OVERALL!$G$2:$G$150,Summary!AC15) -> 0 | AE15: =AD15/$AD$19 -> #DIV/0!
B16: In Progress | C16: =COUNTIF(Orders!$G$2:$G$143,Summary!B16) -> 0 | D16: =C16/$C$19 -> 0 | O16: In Progress | P16: =COUNTIF('Sheet 4'!$G$2:$G$148,Summary!O16) -> 0 | Q16: =P16/$P$19 -> #DIV/0! | AC16: In Progress | AD16: =COUNTIF(OVERALL!$G$2:$G$150,Summary!AC16) -> 0 | AE16: =AD16/$AD$19 -> #DIV/0!
B17: Out of Scope | C17: =COUNTIF(Orders!$G$2:$G$143,Summary!B17) -> 0 | D17: =C17/$C$19 -> 0 | O17: Out of Scope | P17: =COUNTIF('Sheet 4'!$G$2:$G$148,Summary!O17) -> 0 | Q17: =P17/$P$19 -> #DIV/0! | AC17: Out of Scope | AD17: =COUNTIF(OVERALL!$G$2:$G$150,Summary!AC17) -> 0 | AE17: =AD17/$AD$19 -> #DIV/0!
B18: Not Started | C18: =COUNTIF(Orders!$G$2:$G$143,Summary!B18) -> 0 | D18: =C18/$C$19 -> 0 | O18: Not Started | P18: =COUNTIF('Sheet 4'!$G$2:$G$148,Summary!O18) -> 0 | Q18: =P18/$P$19 -> #DIV/0! | AC18: Not Started | AD18: =COUNTIF(OVERALL!$G$2:$G$150,Summary!AC18) -> 0 | AE18: =AD18/$AD$19 -> #DIV/0!
B19: TOTAL | C19: =SUM(C12:C18) -> 9 | O19: TOTAL | P19: =SUM(P12:P18) -> 0 | AC19: TOTAL | AD19: =SUM(AD12:AD18) -> 0
E23: SHEET3 DASHBOARD | Q23: KPI6 DASHBOARD
B25: Execution Progress | O25: Execution Progress
B26: Steps Completed | C26: =SUM(Sheet3!F2:F59) -> 0 | O26: Steps Completed | P26: =SUM('KPI6'!F2:F62) -> 513
B27: Steps Remaining | C27: =SUM(C28-C26) -> 0 | O27: Steps Remaining | P27: =P28-P26 -> 0
B28: Total Steps | C28: =SUM(Sheet3!E2:E59) -> 0 | O28: Total Steps | P28: =SUM('KPI6'!E2:E62) -> 513
B30: % Complete | C30: =C26/C28 -> #DIV/0! | O30: % Complete | P30: =P26/P28 -> 1
B32: Script Status | O32: Script Status
B33: Pass | C33: =COUNTIF(Sheet3!$G$2:$G$149,Summary!B33) -> 0 | D33: =C33/$C$40 -> #DIV/0! | O33: Pass | P33: =COUNTIF('KPI6'!$G$2:$G$144,Summary!O33) -> 61 | Q33: =P33/$P$40 -> 0.59223301
B34: Fail | C34: =COUNTIF(Sheet3!$G$2:$G$149,Summary!B34) -> 0 | D34: =C34/$C$40 -> #DIV/0! | O34: Fail | P34: =COUNTIF('KPI6'!$G$2:$G$144,Summary!O34) -> 0 | Q34: =P34/$P$40 -> 0
B35: No Run | C35: =COUNTIF(Sheet3!$G$2:$G$149,Summary!B35) -> 0 | D35: =C35/$C$40 -> #DIV/0! | O35: No Run | P35: =COUNTIF('KPI6'!$G$2:$G$144,Summary!O35) -> 0 | Q35: =P35/$P$40 -> 0
B36: Not Completed | C36: =COUNTIF(Sheet3!$G$2:$G$149,Summary!B36) -> 0 | D36: =C36/$C$40 -> #DIV/0! | O36: Not Completed | P36: =COUNTIF('KPI6'!$G$2:$G$144,Summary!O36) -> 0 | Q36: =P36/$P$40 -> 0
B37: In Progress | C37: =COUNTIF(Sheet3!$G$2:$G$149,Summary!B37) -> 0 | D37: =C37/$C$40 -> #DIV/0! | O37: In Progress | P37: =COUNTIF('KPI6'!$G$2:$G$144,Summary!O37) -> 0 | Q37: =P37/$P$40 -> 0
B38: Out of Scope | C38: =COUNTIF(Sheet3!$G$2:$G$149,Summary!B38) -> 0 | D38: =C38/$C$40 -> #DIV/0! | O38: Out of Scope | P38: =COUNTIF('KPI6'!$G$2:$G$144,Summary!O38) -> 42 | Q38: =P38/$P$40 -> 0.40776699
B39: Not Started | C39: =COUNTIF(Sheet3!$G$2:$G$149,Summary!B39) -> 0 | D39: =C39/$C$40 -> #DIV/0! | O39: Not Started | P39: =COUNTIF('KPI6'!$G$2:$G$144,Summary!O39) -> 0 | Q39: =P39/$P$40 -> 0
B40: TOTAL | C40: =SUM(C33:C39) -> 0 | O40: TOTAL | P40: =SUM(P33:P39) -> 103

Sheet Orders
A1: Test ID | B1: Test Scenario | C1: Test Steps | D1: Outcome Expected | E1: # of Steps | F1: Completed Steps | G1: Status | H1: Notes | I1: Test Data Used | J1: Executed By | K1: Approved By | L1: Tests to do
A2: KO01 | B2: Adult - New Order - Verified Address - GPS Bail-Curfew only | C2: 1. create Interaction 2. create Contact 3. create Device Wearer 4. create Case 5. create Monitoring Order 6. create Monitoring Requirements 7. create Monitoring Configuration 8. create Work Order 9. Create Work Order Task 10. Install | D2: - interaction, case, mon order, work order and work order task created | E2: 10 | F2: 10 | G2: Pass | H2: DEVWR0101676 / MON10119207 | J2: Luke | L2: KP04 KP05 KP06 KP10 KP11 KP12 KP13 KP14 KP15 KP16 KP17 KP18
A3: KO02 | B3: Adult - New Order - Verified Address - GPS Bail- Location | C3: 1. create Interaction 2. create Contact 3. create Device Wearer 4. create Case 5. create Monitoring Order 6. create Monitoring Requirements 7. create Monitoring Configuration 8. create Work Order 9. Create Work Order Task 10. Install | D3: - interaction, case, mon order, work order and work order task created | E3: 10 | F3: 10 | G3: Pass | H3: DEVWR0101679 / MON10119208 | J3: Luke | L3: KP01 KP02 KP03 KP07 KP08 KP09
A4: KO03 | B4: Adult - New Order - Verified Address - GPS Bail-Curfew and Location | C4: 1. create Interaction 2. create Contact 3. create Device Wearer 4. create Case 5. create Monitoring Order 6. create Monitoring Requirements 7. create Monitoring Configuration 8. create Work Order 9. Create Work Order Task 10. Install | D4: - interaction, case, mon order, work order and work order task created | E4: 10 | F4: 10 | G4: Pass | H4: DEVWR0101684-MON10119211 | J4: Luke | L4: KP19 KP20 KP21 KP22 KP23 KP24 KP25 KP26 KP27 KP28 KP29 KP30
A5: KO04 | B5: Adult-Non-Bail-Community-curfew | C5: 1. create Interaction 2. create Contact 3. create Device Wearer 4. create Case 5. create Monitoring Order 6. create Monitoring Requirements 7. create Monitoring Configuration 8. create Work Order 9. Create Work Order Task 10. Install | D5: - interaction, case, mon order, work order and work order task created | E5: 10 | F5: 10 | G5: Pass | H5: DEVWR0101691 / MON10119213 | J5: Luke | L5: KP32 KP33 KP34 KP44 KP45 KP46 KP47 KP48 KP49
A6: KO05 | B6: Adult-Non-Bail-Post Release- location | C6: 1. create Interaction 2. create Contact 3. create Device Wearer 4. create Case 5. create Monitoring Order 6. create Monitoring Requirements 7. create Monitoring Configuration 8. create Work Order 9. Create Work Order Task 10. Install | D6: - interaction, case, mon order, work order and work order task created | E6: 10 | F6: 10 | G6: Pass | H6: DEVWR0101694 / MON10119216 | J6: Luke | L6: KP35 KP36 KP37 KP38 KP39 KP40 KP41 KP42
A7: KO06 | B7: Adult-Non-Bail-Post Release- Curfew and Location | C7: 1. create Interaction 2. create Contact 3. create Device Wearer 4. create Case 5. create Monitoring Order 6. create Monitoring Requirements 7. create Monitoring Configuration 8. create Work Order 9. Create Work Order Task 10. Install | D7: - interaction, case, mon order, work order and work order task created | E7: 10 | F7: 10 | G7: Pass | H7: DEVWR0101702 / MON10119224 | J7: Luke | L7: KP49 KP50 KP51 KP51 KP52 KP53 KP54 KP55 KP56 KP57 KP58 KP59 KP60 KP61
A8: KO07 | B8: Immigration-GPS-CURFEW | C8: 1. create Interaction 2. create Contact 3. create Device Wearer 4. create Case 5. create Monitoring Order 6. create Monitoring Requirements 7. create Monitoring Configuration 8. create Work Order 9. Create Work Order Task 10. Install | D8: - interaction, case, mon order, work order and work order task created | E8: 10 | F8: 10 | G8: Pass | H8: DEVWR0101714 / MON10119231 | J8: Luke | L8: KP65 KP66 KP67 KP74 KP75 KP76 KP77 KP78 KP79
A9: KO08 | B9: Immigration-GPS-LOCATION | C9: 1. create Interaction 2. create Contact 3. create Device Wearer 4. create Case 5. create Monitoring Order 6. create Monitoring Requirements 7. create Monitoring Configuration 8. create Work Order 9. Create Work Order Task 10. Install | D9: - interaction, case, mon order, work order and work order task created | E9: 10 | F9: 10 | G9: Pass | H9: DEVWR0101719 / MON10119238 | J9: Luke | L9: KP62 KP63 KP64 KP68 KP69 KP70 KP71 KP72 KP73
A10: K009 | B10: Immigration-GPS-Location and curfew | C10: 1. create Interaction 2. create Contact 3. create Device Wearer 4. create Case 5. create Monitoring Order 6. create Monitoring Requirements 7. create Monitoring Configuration 8. create Work Order 9. Create Work Order Task 10. Install | D10: - interaction, case, mon order, work order and work order task created | E10: 10 | F10: 10 | G10: Pass | H10: DEVWR0101726 / MON10119241 | J10: Luke | L10: KP80 KP81 KP82 KP83 KP84 KP85 KP86 KP87 KP88 KP89 KP90 KP91
SZ78: Column1

Sheet KPI6
A1: Test ID | B1: Test Scenario | C1: Test Steps | D1: Outcome Expected | E1: # of Steps | F1: Completed Steps | G1: Status | H1: Notes | I1: Data notes | J1: Tested by | K1: order used
A2: KP01 | B2: AL02-Bail - answered | C2: AL02 has been created - API to PD displayed in activity stream - call made to HMU - call answered - call ends - update investigation outcome field on case to Violation confirmed - update resolution field to completed - update state to resolved | D2: -Interaction created in ServiceNow with Short description: AL02 Tamper of worn device non curfew order - auto set first response date and time field in table - First Call Outcome data field populated on case - interaction updated as Closed Complete - investigation outcome field set to Violation confirmed - resolution field set to completed - state set to resolved | E2: 8 | F2: 8 | G2: Pass | K2: KO02
A3: KP02 | B3: AL02-Bail - abandoned | C3: AL02 has been created - API to PD displayed in activity stream - call made to HMU - listen to 50% of call then abandon call - call ends - update investigation outcome field on case to Violation confirmed - update resolution field to completed - update state to resolved | D3: -Interaction created in ServiceNow with Short description: AL02 Tamper of worn device non curfew order - auto set first response date and time field in table - First Call Outcome data field populated on case - interaction updated as Call Abandoned - investigation outcome field set to Violation confirmed - resolution field set to completed - state set to resolved | E3: 8 | F3: 8 | G3: Pass | K3: KO02
A4: KP03 | B4: AL02-Bail - not answered | C4: AL02 has been created - API to PD displayed in activity stream - call made to HMU - call not answered - update investigation outcome field to Violation confirmed - update resolution field to completed - update state to resolved | D4: - API to PD displayed in activity stream - auto set first response date and time field in table - First Call Outcome data field populated on case - no interaction created - investigation outcome field set to Violation confirmed - resolution field set to completed - state set to resolved" | E4: 8 | F4: 8 | G4: Pass | K4: KO02
A5: KP04 | B5: AL03-Bail - answered | C5: AL03 has been created - API to PD displayed in activity stream - call made to HMU - call answered - call ends - update investigation outcome field on case to Violation confirmed - update resolution field to completed - update state to resolved | D5: -Interaction created in ServiceNow with Short description: AL03 Tamper of worn device (curfew order) - auto set first response date and time field in table - First Call Outcome data field populated on case - interaction updated as Closed Complete - investigation outcome field set to Violation confirmed - resolution field set to completed - state set to resolved | E5: 8 | F5: 8 | G5: Pass | K5: KO01
A6: KP05 | B6: AL03-Bail - abandoned | C6: AL03 has been created - API to PD displayed in activity stream - call made to HMU - listen to 50% of call then abandon call - call ends - update investigation outcome field on case to Violation confirmed - update resolution field to completed - update state to resolved | D6: -Interaction created in ServiceNow with Short description: AL03 Tamper of worn device (curfew order) - auto set first response date and time field in table - First Call Outcome data field populated on case - interaction updated as Call Abandoned - investigation outcome field set to Violation confirmed - resolution field set to completed - state set to resolved | E6: 8 | F6: 8 | G6: Pass | K6: KO01
A7: KP06 | B7: AL03-Bail - not answered | C7: AL03 has been created - API to PD displayed in activity stream - call made to HMU - call not answered - update investigation outcome field on case to Violation confirmed - update resolution field to completed - update state to resolved | D7: - API to PD displayed in activity stream - auto set first response date and time field in table - First Call Outcome data field populated on case - needs attention flag updated on case - no interaction created - investigation outcome field set to Violation confirmed - resolution field set to completed - state set to resolved | E7: 7 | F7: 7 | G7: Pass | K7: KO01
A8: KP07 | B8: AL04-Bail - answered | C8: AL04 has been created - API to PD displayed in activity stream - call made to HMU - call answered - call ends - update investigation outcome field on case to Violation confirmed - update resolution field to completed - update state to resolved | D8: -Interaction created in ServiceNow with Short description: AL04 Power off of Curfew Monitoring Equipment - auto set first response date and time field in table - First Call Outcome data field populated on case - interaction updated as Closed Complete - investigation outcome field set to Violation confirmed - resolution field set to completed - state set to resolved | E8: 8 | F8: 8 | G8: Pass | K8: KO02
A9: KP08 | B9: AL04-Bail - abandoned | C9: "AL04 has been created - API to PD displayed in activity stream - call made to HMU - listen to 50% of call then abandon call - call ends - update investigation outcome field on case to Violation confirmed - update resolution field to completed - update state to resolved | D9: -Interaction created in ServiceNow with Short description: AL04 Power off of Curfew Monitoring Equipment - auto set first response date and time field in table - First Call Outcome data field populated on case - interaction updated as Call Abandoned - investigation outcome field set to Violation confirmed - resolution field set to completed - state set to resolved | E9: 8 | F9: 8 | G9: Pass | K9: KO02
A10: KP09 | B10: AL04-Bail - not answered | C10: AL04 has been created - API to PD displayed in activity stream - call made to HMU - call not answered - update investigation outcome field to Violation confirmed - update resolution field to completed - update state to resolved | D10: - API to PD displayed in activity stream - auto set first response date and time field in table - First Call Outcome data field populated on case - no interaction created - investigation outcome field set to Violation confirmed - resolution field set to completed - state set to resolved" | E10: 8 | F10: 8 | G10: Pass | K10: KO02
A11: KP10 | B11: AL05-Bail - answered | C11: AL05 has been created - API to PD displayed in activity stream - call made to HMU - call answered - call ends - update investigation outcome field on case to Violation confirmed - update resolution field to completed - update state to resolved | D11: - API to PD displayed in activity stream - auto set first response date and time field in table - First Call Outcome data field populated on case - no interaction created - investigation outcome field set to Violation confirmed - resolution field set to completed - state set to resolved" | E11: 8 | F11: 8 | G11: Pass | K11: KO01
A12: KP11 | B12: AL05-Bail - abandoned | C12: AL05 has been created - API to PD displayed in activity stream - call made to HMU -Interaction created in ServiceNow with Short description: AL02 Tamper of worn device (non-curfew order) -Listen to 50% of call-Call Adbandoned - call ends - interaction closed - auto set first response date and time field -investigation outcome field set to Violation confirmed - resolution field set to completed - state set to resolved -save -run KPI 6 report -Produce Breach Pack | D12: "- interaction created as WIP - auto set first response date and time field breach pack to send to RO mandatory | E12: 14 | F12: 14 | G12: Pass | K12: KO01
A13: KP12 | B13: AL05-Bail - not answered | C13: AL05 has been created - API to PD displayed in activity stream - call made to HMU - call not answered - update investigation outcome field to Violation confirmed - update resolution field to completed - update state to resolved | D13: - API to PD displayed in activity stream - auto set first response date and time field in table - First Call Outcome data field populated on case - no interaction created - investigation outcome field set to Violation confirmed - resolution field set to completed - state set to resolved" | E13: 8 | F13: 8 | G13: Pass | K13: KO01
... A19: KP18 | B19: AL10-Bail - not answered | C19: AL10 has been created - API to PD displayed in activity stream - call made to HMU - call not answered - update investigation outcome field to Violation confirmed - update resolution field to completed - update state to resolved | D19: - API to PD displayed in activity stream - First Call Outcome data field populated on case- no interaction created - investigation outcome field set to Violation confirmed - resolution field set to completed - state set to resolved" | E19: 8 | F19: 8 | G19: Pass | K19: KO01
A20: KP19 | B20: AL19-Bail - answered | C20: AL19 has been created - API to PD displayed in activity stream - call made to HMU -interaction created in ServiceNow with Short description: AL19-Missing Status Check - call ends - interaction closed | D20: - investigation outcome field set to Violation confirmed - resolution field set to completed - state set to resolved | E20: 6 | F20: 6 | G20: Out of Scope | H20: Tested as part of KP102
A21: KP20 | B21: AL19-Bail - abandoned | C21: AL19 has been created - API to PD displayed in activity stream - call made to HMU -interaction created in ServiceNow with Short description: AL19-Missing Status Check -Listen to 50% of call - call ends | D21: - interaction created as WIP | E21: 6 | F21: 6 | G21: Out of Scope | H21: Tested as part of KP102
A22: KP21 | B22: AL19-Bail - not answered | C22: AL19 has been created - API to PD displayed in activity stream - call made to HMU unsuccesful message in actiivity stream - needs attention flag updated | D22: activity stream updated needs attention flag updated after 1 hour | E22: 5 | F22: 5 | G22: Out of Scope | H22: Tested as part of KP102
A23: KP22 | B23: AL20- BAIL - answered | C23: AL20 has been created - API to PD displayed in activity stream - call made to HMU - call answered - call ends - update investigation outcome field on case to Violation confirmed - update resolution field to completed - update state to resolved | D23: -Interaction created in ServiceNow with Short description: AL20 No movement of Device-Wearer - auto set first response date and time field in table - First Call Outcome data field populated on case - interaction updated as Closed Complete - investigation outcome field set to Violation confirmed - resolution field set to completed - state set to resolved | E23: 8 | F23: 8 | G23: Pass | K23: KO03
A24: KP23 | B24: AL20-BAIL - abandoned | C24: AL20 has been created - API to PD displayed in activity stream - call made to HMU - listen to 50% of call then abandon call - call ends - update investigation outcome field on case to Violation confirmed - update resolution field to completed - update state to resolved | D24: -Interaction created in ServiceNow with Short description: AL20 No movement of Device-Wearer - auto set first response date and time field in table - First Call Outcome data field populated on case - interaction updated as Call Abandoned - investigation outcome field set to Violation confirmed - resolution field set to completed - state set to resolved | E24: 8 | F24: 8 | G24: Pass | K24: KO03
A25: KP24 | B25: AL20-BAIL- not answered | C25: AL20 has been created - API to PD displayed in activity stream - call made to HMU - call not answered - update investigation outcome field to Violation confirmed - update resolution field to completed - update state to resolved | D25: - API to PD displayed in activity stream - First Call Outcome data field populated on case - no interaction created - investigation outcome field set to Violation confirmed - resolution field set to completed - state set to resolved" | E25: 8 | F25: 8 | G25: Pass | K25: KO03
A26: KP25 | B26: AL21-Bail - answered | C26: AL21 has been created - API to PD displayed in activity stream - call made to HMU -interaction created in ServiceNow with Short description: AL21-Non-charged Device Low Battery. Battery running low - call ends - interaction closed | D26: - investigation outcome field set to Violation confirmed - resolution field set to completed - state set to resolved | E26: 6 | F26: 6 | G26: Out of Scope | H26: AL21 not part of KPI6 - do not trigger PD calls
A27: KP26 | B27: AL21-Bail - abandoned | C27: AL21 has been created - API to PD displayed in activity stream - call made to HMU -interaction created in ServiceNow with Short description: AL21-Non-charged Device Low Battery. Battery running low -Listen to 50% of call - call ends | D27: - interaction created as WIP | E27: 6 | F27: 6 | G27: Out of Scope | H27: AL21 not part of KPI6 - do not trigger PD calls
A28: KP27 | B28: AL21-Bail - not answered | C28: AL21 has been created - API to PD displayed in activity stream - call made to HMU -unsuccesful message in actiivity stream - needs attention flag updated | D28: activity stream updated needs attention flag updated after 1 hour | E28: 5 | F28: 5 | G28: Out of Scope | H28: AL21 not part of KPI6 - do not trigger PD calls
A29: KP28 | B29: AL22-BAIL - answered | C29: AL22 has been created - API triggered to PD Battery Alert campaign - PD call made to HMU - call answered - call ends - on case select 'Violation confirmed' in Investigation Outcome field - set case state to resolved - insert text in Work notes (private) - insert Complete in Resolution code - insert text in Resolution notes - select Save | D29: - API to PD displayed in activity stream - interaction created in ServiceNow with Short description: AL22 Automated voice message to Device Wearer - chat summary updated on interaction - interaction closed - case set to resolved and data fields updated | E29: 11 | F29: 11 | G29: Pass | K29: KO03
A30: KP29 | B30: AL22-BAIL - abandoned | C30: AL22 has been created - API triggered to PD Battery Alert campaign - PD call made to HMU - call answered but abandon call after 50% of message heard - call ends - set interaction state to Closed Abandoned - on case select 'Violation confirmed' in Investigation Outcome field - set case state to resolved - insert text in Work notes (private) - insert Complete in Resolution code - insert text in Resolution notes - select Save | D30: - API to PD displayed in activity stream - interaction created in ServiceNow with Short description: AL22 Automated voice message to Device Wearer - chat summary updated on interaction - interaction set to Work In Progress state - interaction updated to Closed Abandoned state - case set to resolved and data fields updated | E30: 12 | F30: 12 | G30: Pass | K30: KO03
A31: KP30 | B31: AL22- BAIL - not answered | C31: AL22 has been created - API triggered to PD Battery Alert campaign - PD call made to HMU - call not answered - on case select 'Violation confirmed' in Investigation Outcome field - set case state to resolved - insert text in Work notes (private) - insert Complete in Resolution code - insert text in Resolution notes - select Save | D31: - API to PD displayed in activity stream - no interaction created - unsuccessful work note added - needs attention flag updated on case - case set to resolved and data fields updated | E31: 9 | F31: 9 | G31: Pass | K31: KO03
A32: KP31 | B32: STRY0086547-Hiding the propose solution UI action on enforcement cases | C32: Find EMS case make sure it is an open Case there shouldn't be a 'Propose solution'button | D32: Then I will NO longer see the 'Propose Solution' button | E32: 3 | F32: 3 | G32: Pass
A33: KP32 | B33: AL02-NON BAIL- answered | C33: " AL02 has been created - API to PD displayed in activity stream - call made to HMU -call answered -Interaction created in ServiceNow with Short description: AL02 Tamper of worn device (non-curfew order) - call ends - interaction closed - auto set first response date and time field -investigation outcome field set to Violation confirmed - resolution field set to completed - state set to resolved -run KPI 6 report | D33: - auto set first response date and time field -manually investigation outcome field set to Violation confirmed - resolution field set to completed - state set to resolved | E33: 12 | F33: 12 | G33: Pass | K33: KO04
A34: KP33 | B34: AL02-NON BAIL - abandoned | C34: AL02 has been created - API to PD displayed in activity stream - call made to HMU -Interaction created in ServiceNow with Short description: AL02 Tamper of worn device (non-curfew order) -Listen to 50% of call - call ends - interaction closed - auto set first response date and time field -investigation outcome field set to Violation confirmed - resolution field set to completed - state set to resolved -run KPI 6 report | D34: - interaction created as WIP - auto set first response date and time field | E34: 12 | F34: 12 | G34: Pass | K34: KO04
A35: KP34 | B35: AL02-NON BAIL - not answered | C35: AL02 has been created - API to PD displayed in activity stream - call made to HMU unsuccesful message in actiivity stream - needs attention flag updated -run KPI6 report auto set first response date and time field -investigation outcome field set to Violation confirmed - resolution field set to completed - state set to resolved | D35: - auto set first response date and time field | E35: 10 | F35: 10 | G35: Pass | K35: KO04
A36: KP35 | B36: AL03-NON BAIL - answered | C36: AL03 has been created - API to PD displayed in activity stream - call made to HMU - call answered - call ends - update investigation outcome field on case to Violation confirmed - update resolution field to completed - update state to resolved | D36: -Interaction created in ServiceNow with Short description: AL03 Tamper of worn device (curfew order) - auto set first response date and time field in table - First Call Outcome data field populated on case - interaction updated as Closed Complete - investigation outcome field set to Violation confirmed - resolution field set to completed - state set to resolved | E36: 8 | F36: 8 | G36: Pass | K36: KO05
A37: KP36 | B37: AL03-NON BAIL - abandoned | C37: AL03 has been created - API to PD displayed in activity stream - call made to HMU - listen to 50% of call then abandon call - call ends - update investigation outcome field on case to Violation confirmed - update resolution field to completed - update state to resolved | D37: -Interaction created in ServiceNow with Short description: AL03 Tamper of worn device (curfew order) - auto set first response date and time field in table - First Call Outcome data field populated on case - interaction updated as Call Abandoned - investigation outcome field set to Violation confirmed - resolution field set to completed - state set to resolved | E37: 8 | F37: 8 | G37: Pass | K37: KO05
A38: KP37 | B38: AL03-NON BAIL - not answered | C38: AL03 has been created - API to PD displayed in activity stream - call made to HMU - call not answered - update investigation outcome field on case to Violation confirmed - update resolution field to completed - update state to resolved | D38: - API to PD displayed in activity - auto set first response date and time field in table - First Call Outcome data field populated on case - needs attention flag updated on case - no interaction created - investigation outcome field set to Violation confirmed - resolution field set to completed - state set to resolved | E38: 8 | F38: 8 | G38: Pass | K38: KO05
A39: KP38 | B39: AL04-NON BAIL- answered | C39: AL04 has been created - API to PD displayed in activity stream - call made to HMU - call answered - call ends - update investigation outcome field on case to Violation confirmed - update resolution field to completed - update state to resolved | D39: -Interaction created in ServiceNow with Short description: AL04 Power off of Curfew Monitoring Equipment - auto set first response date and time field in table - First Call Outcome data field populated on case - interaction updated as Closed Complete - investigation outcome field set to Violation confirmed - resolution field set to completed - state set to resolved | E39: 8 | F39: 8 | G39: Pass | K39: KO05
A40: KP39 | B40: AL04-NON BAIL - abandoned | C40: "AL04 has been created - API to PD displayed in activity stream - call made to HMU - listen to 50% of call then abandon call - call ends - update investigation outcome field on case to Violation confirmed - update resolution field to completed - update state to resolved | D40: -Interaction created in ServiceNow with Short description: AL04 Power off of Curfew Monitoring Equipment - auto set first response date and time field in table - First Call Outcome data field populated on case - interaction updated as Call Abandoned - investigation outcome field set to Violation confirmed - resolution field set to completed - state set to resolved | E40: 8 | F40: 8 | G40: Pass | K40: KO05
A41: KP40 | B41: AL04-NON BAIL - not answered | C41: AL04 has been created - API to PD displayed in activity stream - call made to HMU - call not answered - update investigation outcome field to Violation confirmed - update resolution field to completed - update state to resolved | D41: - API to PD displayed in activity - auto set first response date and time field in table - First Call Outcome data field populated on case - no interaction created - investigation outcome field set to Violation confirmed - resolution field set to completed - state set to resolved" | E41: 8 | F41: 8 | G41: Pass | K41: KO05
A42: KP41 | B42: AL05-NON BAIL - answered | C42: AL05 has been created - API to PD displayed in activity stream - call made to HMU - call answered - call ends - update investigation outcome field on case to Violation confirmed - update resolution field to completed - update state to resolved | D42: -Interaction created in ServiceNow with Short description: AL05 Movement of Home Monitoring Unit - auto set first response date and time field in table - First Call Outcome data field populated on case - interaction updated as Closed Complete - investigation outcome field set to Violation confirmed - resolution field set to completed - state set to resolved | E42: 8 | F42: 8 | G42: Pass | K42: KO05
A43: KP42 | B43: AL05-NON BAIL - abandoned | C43: AL05 has been created - API to PD displayed in activity stream - call made to HMU -Interaction created in ServiceNow with Short description: AL02 Tamper of worn device (non-curfew order) -Listen to 50% of call-Call Adbandoned - call ends - interaction closed - auto set first response date and time field -investigation outcome field set to Violation confirmed - resolution field set to completed - state set to resolved -save -run KPI 6 report -Produce Breach Pack | D43: "- interaction created as WIP - auto set first response date and time field breach pack to send to RO mandatory | E43: 14 | F43: 14 | G43: Pass | K43: KO05
A44: KP43 | B44: AL05-NON BAIL - not answered | C44: "AL05 has been created - API to PD displayed in activity stream - call made to HMU unsuccesful message in actiivity stream - needs attention flag updated -run KPI6 report auto set first response date and time field -investigation outcome field set to Violation confirmed - resolution field set to completed - state set to Closed -save -produce Breach Pack -Run KPI6 report " | D44: breach pack to send to RO mandatory Auto set first response date and time field | E44: 13 | F44: 13 | G44: Pass | K44: KO05
... A50: KP49 | B50: AL10-NON BAIL - not answered | C50: "AL10 has been created - API to PD displayed in activity stream - call made to HMU unsuccesful message in actiivity stream - needs attention flag updated auto set first response date and time field -investigation outcome field set to Violation confirmed - resolution field set to completed - state set to Closed -Run KPI6 report " | D50: - auto set first response date and time field | E50: 10 | F50: 10 | G50: Pass | K50: KO04
...

Sheet Sheet3
A1: Test ID | B1: Test Scenario | C1: Test Steps | D1: Outcome Expected | E1: # of Steps | F1: Completed Steps | G1: Status | H1: Notes | I1: Test Data Used | J1: Executed By | K1: Approved By

Sheet Sheet 4
A1: Test ID | B1: Test Scenario | C1: Test Steps | D1: Outcome Expected | E1: # of Steps | F1: Completed Steps | G1: Status | H1: Notes | I1: Test Data Used | J1: Executed By | K1: Approved By

Sheet Validation
A1: Pass
A2: Fail
A3: No Run
A4: Not Completed
A5: In Progress
A6: Out of Scope
A7: Development
A8: Blocked
A9: Not Started

Sheet Defects
A1: Incident / JIRA ref | B1: Test ID | C1: Issue | D1: Description | E1: Category | F1: Impact Rating (H-M-L) | G1: Date Opened | H1: Date Resolved | I1: Target Release Date | J1: Status | K1: Post Production Check Y/N | L1: Resolution | M1: Release | N1: Notes
A2: 1
A3: 2
A4: 3
A5: 4
A6: 5
A7: 6
A8: 7
A9: 8
A10: 9
A11: 10
A12: 11
A13: 12
... A100: 99
G1048576: 6.1.25

Sheet Sheet1
B2: Testing Timeline
B5: 19th | E5: 20th | H5: 21st | I5: 24th | J5: 25th | K5: 26th | L5: 27th | M5: 28th
A6: ST | B6: OE44 * Install alcohol kit | D6: ST | E6: DV50 * Asset Manager BPSS persona | G6: ST | H6: DV50 * Asset Manager BPSS persona
A7: KW | B7: DV41 * Field Service Officer persona | D7: ST | E7: DV51 * Asset Manager CTC persona | G7: ST | H7: DV51 * Asset Manager CTC persona
A8: KW | B8: DV42 * Field Service Officer SPECIALS persona | D8: ST | E8: DV21 * Field Service Scheduler BPSS persona | G8: ST | H8: DV21 * Field Service Scheduler BPSS persona
A9: LJ | B9: DV44 * Quality Assurance CTC persona | D9: ST | E9: DV22 * Field Service Scheduler CTC persona | G9: ST | H9: DV22 * Field Service Scheduler CTC persona
A10: EM | B10: DV48 * CMT Immigration persona FAILED | D10: TL / MHI | E10: TA08 * atv breaches | H10: TA31
A11: EM | B11: DV49 * CMT (MoJ) personas PASSED | D11: ST | E11: OEO7 * install following OE01 decom | H11: TA10 / OE70
A12: ST | B12: OE69 * install NFD | D12: EM | E12: TA04 *EXCLUSION | G12: EM | H12: TA04 *EXCLUSION
A13: EM | B13: TA09 / OE69 * start the AL18 process | D13: EM | E13: TA30 *AL15 | G13: EM | H13: TA30 *AL15
A14: TL / MHI | B14: TA01 / OE01 * finish generating the atvs & breach packs | D14: EM | E14: TA47 * AL24 -SPOOF | G14: EM | H14: TA47 * AL24 -SPOOF
A15: TL / MHI | B15: TA52 / OE01 * generate AL04 | D15: LJ | E15: TA48 * AL20 | H15: OE06
A16: ST | B16: TA43 / OE01 * request spoof event from AUEM | D16: LJ | E16: OE04 * check further visit has generated after previous visit booked off as faulty equipment | H16: OE76
A17: ST | B17: OE01 * decom kit once event has been spoofed | D17: ST | E17: OE01 * decom kit | H17: OE08
A18: EM / ST & KW | B18: OE04 * Create order * Assign WOT to Mark * 2x no show visits | D18: ST | E18: OE03 * 2x no show | H18: TA41
A19: ST & KW | B19: OE03 * Assign WOT to Mark * 2x no show visits | D19: TL / MHI | E19: TA02 * 2x no show breach | H19: OE09 | I19: NO SHOW
A20: TL / MHI | B20: TA05 / OE02 * Create multiple exclusions Day 1 | D20: TL / MHI | E20: TA05 / OE02 * Create multiple exclusions Day 2 | H20: OE10 | I20: BOOK OFFS
A21: TL / MHI & ST | B21: TA11 / OE02 * Generate strap tamper * Complete tamper visit | D21: TL / MHI | E21: TA46 * breach | H21: OE15
A22: TL / MHI | B22: TA33 / OE20 * battery dead | D22: ST | E22: TA03 * 2x no show | H22: OE16
A23: MS | B23: OE08 * Create order | D23: TL / MHI | E23: TA03 * breach | H23: OE17
A24: MS | B24: OE09 * Create order | D24: ST | E24: OE11 * 2x no show | H24: OE12
A25: MS | B25: OE10 * Create order | D25: TL / MHI | E25: TA13 * breach | H25: OE13
A26: MS | B26: OE11 * Create order | D26: LJ | E26: TA68 * breach | G26: LJ | H26: TA68 * breach
A27: MS | B27: OE12 * Create order | D27: EM | E27: OE18 * decom
A28: MS | B28: OE13 * Create order | D28: MS | E28: OE15 * create order
A29: CL | B29: OE45 * Create order | D29: MS | E29: OE16 * create order
A30: CL | B30: OE46 * Create order | D30: MS | E30: OE17 * create order
A31: CL | B31: OE47 * Create order | D31: MS | E31: OE19 * create order
A32: ST | B32: OE14 * decom kit | D32: MS | E32: OE21 * create order
A33: ST | B33: OE20 * install kit | D33: MS | E33: OE22 * create order
A34: TL / MHI | B34: TA08 * start atv breaches | D34: MS | E34: OE23 * create order
D35: MS | E35: OE24 * create order
D36: MS | E36: OE25 * create order
D37: MS | E37: OE26 * create order | G37: MS | H37: OE26 * create order
D38: MS | E38: OE27 * create order
D39: MS | E39: OE28 * create order | G39: MS | H39: OE28 * create order
D40: CL | E40: OE29 * create order | G40: MS | H40: OE29 * create order
D41: CL | E41: OE30 * create order | G41: MS | H41: OE30 * create order
D42: CL | E42: OE31 * create order | G42: MS | H42: OE31 * create order
D43: CL | E43: AC01 * create order | G43: CL | H43: AC01 * create order
...

Sheet OVERALL
A1: Test ID | B1: Test Scenario | C1: Test Steps | D1: Outcome Expected | E1: # of Steps | F1: Completed Steps | G1: Status | H1: Notes | I1: Issue/Defect | J1: SERCO JIRA ID | K1: SNOW defect ID | L1: Approved By
AF12: =COUNTIF('Sheet 4'!$G$2:$G$41,Summary!AC12) -> 0
